{
 "cells": [
  {
   "cell_type": "code",
   "execution_count": 1,
   "metadata": {},
   "outputs": [],
   "source": [
    "import pandas as pd\n",
    "import numpy as np"
   ]
  },
  {
   "cell_type": "code",
   "execution_count": 2,
   "metadata": {},
   "outputs": [
    {
     "name": "stderr",
     "output_type": "stream",
     "text": [
      "C:\\Users\\Fakhruddin\\Anaconda3\\lib\\site-packages\\IPython\\core\\interactiveshell.py:3057: DtypeWarning: Columns (9,10,14,15,21,41,51) have mixed types.Specify dtype option on import or set low_memory=False.\n",
      "  interactivity=interactivity, compiler=compiler, result=result)\n"
     ]
    }
   ],
   "source": [
    "invoice_data=pd.read_csv('C:\\\\Users\\\\Fakhruddin\\\\Capstone Project\\\\Mahindra First Choice Dataset\\\\Final_invoice.csv')"
   ]
  },
  {
   "cell_type": "code",
   "execution_count": 3,
   "metadata": {},
   "outputs": [
    {
     "data": {
      "text/plain": [
       "Index(['Unnamed: 0', 'Amt Rcvd From Custom', 'Amt Rcvd From Ins Co',\n",
       "       'Area / Locality', 'CGST(14%)', 'CGST(2.5%)', 'CGST(6%)', 'CGST(9%)',\n",
       "       'CITY', 'Cash /Cashless Type', 'Claim No.', 'Cust Type', 'Customer No.',\n",
       "       'District', 'Expiry Date', 'Gate Pass Date', 'Gate Pass Time',\n",
       "       'IGST(12%)', 'IGST(18%)', 'IGST(28%)', 'IGST(5%)', 'Insurance Company',\n",
       "       'Invoice Date', 'Invoice No', 'Invoice Time', 'Job Card No',\n",
       "       'JobCard Date', 'JobCard Time', 'KMs Reading', 'Labour Total', 'Make',\n",
       "       'Misc Total', 'Model', 'ODN No.', 'OSL Total', 'Order Type',\n",
       "       'Outstanding Amt', 'Parts Total', 'Pin code', 'Plant', 'Plant Name1',\n",
       "       'Policy no.', 'Print Status', 'Recovrbl Exp', 'Regn No',\n",
       "       'SGST/UGST(14%)', 'SGST/UGST(2.5%)', 'SGST/UGST(6%)', 'SGST/UGST(9%)',\n",
       "       'Service Advisor Name', 'TDS amount', 'Technician Name',\n",
       "       'Total Amt Wtd Tax.', 'Total CGST', 'Total GST', 'Total IGST',\n",
       "       'Total SGST/UGST', 'Total Value', 'User ID'],\n",
       "      dtype='object')"
      ]
     },
     "execution_count": 3,
     "metadata": {},
     "output_type": "execute_result"
    }
   ],
   "source": [
    "invoice_data.columns"
   ]
  },
  {
   "cell_type": "code",
   "execution_count": 5,
   "metadata": {},
   "outputs": [
    {
     "name": "stderr",
     "output_type": "stream",
     "text": [
      "C:\\Users\\Fakhruddin\\Anaconda3\\lib\\site-packages\\ipykernel_launcher.py:2: SettingWithCopyWarning: \n",
      "A value is trying to be set on a copy of a slice from a DataFrame.\n",
      "Try using .loc[row_indexer,col_indexer] = value instead\n",
      "\n",
      "See the caveats in the documentation: https://pandas.pydata.org/pandas-docs/stable/user_guide/indexing.html#returning-a-view-versus-a-copy\n",
      "  \n"
     ]
    },
    {
     "data": {
      "text/html": [
       "<div>\n",
       "<style scoped>\n",
       "    .dataframe tbody tr th:only-of-type {\n",
       "        vertical-align: middle;\n",
       "    }\n",
       "\n",
       "    .dataframe tbody tr th {\n",
       "        vertical-align: top;\n",
       "    }\n",
       "\n",
       "    .dataframe thead th {\n",
       "        text-align: right;\n",
       "    }\n",
       "</style>\n",
       "<table border=\"1\" class=\"dataframe\">\n",
       "  <thead>\n",
       "    <tr style=\"text-align: right;\">\n",
       "      <th></th>\n",
       "      <th>State</th>\n",
       "      <th>Order Type</th>\n",
       "      <th>JobCard Date</th>\n",
       "    </tr>\n",
       "  </thead>\n",
       "  <tbody>\n",
       "    <tr>\n",
       "      <th>0</th>\n",
       "      <td>Maharashtra</td>\n",
       "      <td>Paid Service</td>\n",
       "      <td>2014-12-13</td>\n",
       "    </tr>\n",
       "    <tr>\n",
       "      <th>1</th>\n",
       "      <td>Maharashtra</td>\n",
       "      <td>SMC Value Package</td>\n",
       "      <td>2015-01-02</td>\n",
       "    </tr>\n",
       "    <tr>\n",
       "      <th>2</th>\n",
       "      <td>Maharashtra</td>\n",
       "      <td>Running Repairs</td>\n",
       "      <td>2015-01-02</td>\n",
       "    </tr>\n",
       "    <tr>\n",
       "      <th>3</th>\n",
       "      <td>Maharashtra</td>\n",
       "      <td>SMC Redemption</td>\n",
       "      <td>2015-01-03</td>\n",
       "    </tr>\n",
       "    <tr>\n",
       "      <th>4</th>\n",
       "      <td>Maharashtra</td>\n",
       "      <td>Paid Service</td>\n",
       "      <td>2015-01-02</td>\n",
       "    </tr>\n",
       "  </tbody>\n",
       "</table>\n",
       "</div>"
      ],
      "text/plain": [
       "         State         Order Type JobCard Date\n",
       "0  Maharashtra       Paid Service   2014-12-13\n",
       "1  Maharashtra  SMC Value Package   2015-01-02\n",
       "2  Maharashtra    Running Repairs   2015-01-02\n",
       "3  Maharashtra     SMC Redemption   2015-01-03\n",
       "4  Maharashtra       Paid Service   2015-01-02"
      ]
     },
     "execution_count": 5,
     "metadata": {},
     "output_type": "execute_result"
    }
   ],
   "source": [
    "selected_df=invoice_data[['District','Order Type','JobCard Date']]\n",
    "selected_df['JobCard Date']=pd.to_datetime(selected_df['JobCard Date'])\n",
    "selected_df=selected_df.rename(columns={'District':'State'})\n",
    "selected_df.head()"
   ]
  },
  {
   "cell_type": "code",
   "execution_count": 6,
   "metadata": {},
   "outputs": [
    {
     "data": {
      "text/html": [
       "<div>\n",
       "<style scoped>\n",
       "    .dataframe tbody tr th:only-of-type {\n",
       "        vertical-align: middle;\n",
       "    }\n",
       "\n",
       "    .dataframe tbody tr th {\n",
       "        vertical-align: top;\n",
       "    }\n",
       "\n",
       "    .dataframe thead th {\n",
       "        text-align: right;\n",
       "    }\n",
       "</style>\n",
       "<table border=\"1\" class=\"dataframe\">\n",
       "  <thead>\n",
       "    <tr style=\"text-align: right;\">\n",
       "      <th></th>\n",
       "      <th></th>\n",
       "      <th></th>\n",
       "      <th>Order Type</th>\n",
       "    </tr>\n",
       "    <tr>\n",
       "      <th>State</th>\n",
       "      <th>JobCard Date</th>\n",
       "      <th>Order Type</th>\n",
       "      <th></th>\n",
       "    </tr>\n",
       "  </thead>\n",
       "  <tbody>\n",
       "    <tr>\n",
       "      <th rowspan=\"5\" valign=\"top\">Andaman and Nico.In.</th>\n",
       "      <th>2015-09-30</th>\n",
       "      <th>Running Repairs</th>\n",
       "      <td>1</td>\n",
       "    </tr>\n",
       "    <tr>\n",
       "      <th>2015-12-15</th>\n",
       "      <th>Accidental</th>\n",
       "      <td>1</td>\n",
       "    </tr>\n",
       "    <tr>\n",
       "      <th>2015-12-17</th>\n",
       "      <th>Running Repairs</th>\n",
       "      <td>1</td>\n",
       "    </tr>\n",
       "    <tr>\n",
       "      <th>2015-12-31</th>\n",
       "      <th>Running Repairs</th>\n",
       "      <td>1</td>\n",
       "    </tr>\n",
       "    <tr>\n",
       "      <th>2016-07-16</th>\n",
       "      <th>Running Repairs</th>\n",
       "      <td>1</td>\n",
       "    </tr>\n",
       "  </tbody>\n",
       "</table>\n",
       "</div>"
      ],
      "text/plain": [
       "                                                   Order Type\n",
       "State                JobCard Date Order Type                 \n",
       "Andaman and Nico.In. 2015-09-30   Running Repairs           1\n",
       "                     2015-12-15   Accidental                1\n",
       "                     2015-12-17   Running Repairs           1\n",
       "                     2015-12-31   Running Repairs           1\n",
       "                     2016-07-16   Running Repairs           1"
      ]
     },
     "execution_count": 6,
     "metadata": {},
     "output_type": "execute_result"
    }
   ],
   "source": [
    "df=selected_df.groupby(['State','JobCard Date'])['Order Type'].value_counts().to_frame()\n",
    "df.head()"
   ]
  },
  {
   "cell_type": "code",
   "execution_count": 7,
   "metadata": {
    "scrolled": true
   },
   "outputs": [
    {
     "data": {
      "text/html": [
       "<div>\n",
       "<style scoped>\n",
       "    .dataframe tbody tr th:only-of-type {\n",
       "        vertical-align: middle;\n",
       "    }\n",
       "\n",
       "    .dataframe tbody tr th {\n",
       "        vertical-align: top;\n",
       "    }\n",
       "\n",
       "    .dataframe thead th {\n",
       "        text-align: right;\n",
       "    }\n",
       "</style>\n",
       "<table border=\"1\" class=\"dataframe\">\n",
       "  <thead>\n",
       "    <tr style=\"text-align: right;\">\n",
       "      <th></th>\n",
       "      <th>State</th>\n",
       "      <th>JobCard Date</th>\n",
       "      <th>Order Type</th>\n",
       "      <th>Count</th>\n",
       "    </tr>\n",
       "  </thead>\n",
       "  <tbody>\n",
       "    <tr>\n",
       "      <th>0</th>\n",
       "      <td>Andaman and Nico.In.</td>\n",
       "      <td>2015-09-30</td>\n",
       "      <td>Running Repairs</td>\n",
       "      <td>1</td>\n",
       "    </tr>\n",
       "    <tr>\n",
       "      <th>1</th>\n",
       "      <td>Andaman and Nico.In.</td>\n",
       "      <td>2015-12-15</td>\n",
       "      <td>Accidental</td>\n",
       "      <td>1</td>\n",
       "    </tr>\n",
       "    <tr>\n",
       "      <th>2</th>\n",
       "      <td>Andaman and Nico.In.</td>\n",
       "      <td>2015-12-17</td>\n",
       "      <td>Running Repairs</td>\n",
       "      <td>1</td>\n",
       "    </tr>\n",
       "    <tr>\n",
       "      <th>3</th>\n",
       "      <td>Andaman and Nico.In.</td>\n",
       "      <td>2015-12-31</td>\n",
       "      <td>Running Repairs</td>\n",
       "      <td>1</td>\n",
       "    </tr>\n",
       "    <tr>\n",
       "      <th>4</th>\n",
       "      <td>Andaman and Nico.In.</td>\n",
       "      <td>2016-07-16</td>\n",
       "      <td>Running Repairs</td>\n",
       "      <td>1</td>\n",
       "    </tr>\n",
       "  </tbody>\n",
       "</table>\n",
       "</div>"
      ],
      "text/plain": [
       "                  State JobCard Date       Order Type  Count\n",
       "0  Andaman and Nico.In.   2015-09-30  Running Repairs      1\n",
       "1  Andaman and Nico.In.   2015-12-15       Accidental      1\n",
       "2  Andaman and Nico.In.   2015-12-17  Running Repairs      1\n",
       "3  Andaman and Nico.In.   2015-12-31  Running Repairs      1\n",
       "4  Andaman and Nico.In.   2016-07-16  Running Repairs      1"
      ]
     },
     "execution_count": 7,
     "metadata": {},
     "output_type": "execute_result"
    }
   ],
   "source": [
    "df=df.rename(columns={'Order Type':'Count'})\n",
    "df=df.reset_index()\n",
    "df.head()"
   ]
  },
  {
   "cell_type": "code",
   "execution_count": 60,
   "metadata": {},
   "outputs": [
    {
     "data": {
      "text/plain": [
       "(23, 4)"
      ]
     },
     "execution_count": 60,
     "metadata": {},
     "output_type": "execute_result"
    }
   ],
   "source": [
    "df[df['State']=='Goa'].shape"
   ]
  },
  {
   "cell_type": "code",
   "execution_count": 8,
   "metadata": {},
   "outputs": [],
   "source": [
    "from datetime import datetime as datetime\n",
    "import dash\n",
    "import dash_html_components as html\n",
    "import dash_core_components as dcc\n",
    "import plotly\n",
    "from dash.dependencies import Input, Output, State\n",
    "import plotly.graph_objects as go"
   ]
  },
  {
   "cell_type": "code",
   "execution_count": 42,
   "metadata": {},
   "outputs": [
    {
     "ename": "NameError",
     "evalue": "name 'filtered_df' is not defined",
     "output_type": "error",
     "traceback": [
      "\u001b[1;31m---------------------------------------------------------------------------\u001b[0m",
      "\u001b[1;31mNameError\u001b[0m                                 Traceback (most recent call last)",
      "\u001b[1;32m<ipython-input-42-f94c20d52544>\u001b[0m in \u001b[0;36m<module>\u001b[1;34m\u001b[0m\n\u001b[0;32m      2\u001b[0m \u001b[1;33m\u001b[0m\u001b[0m\n\u001b[0;32m      3\u001b[0m trace1= go.Scatter(\n\u001b[1;32m----> 4\u001b[1;33m                     \u001b[0mx\u001b[0m \u001b[1;33m=\u001b[0m \u001b[0mfiltered_df\u001b[0m\u001b[1;33m[\u001b[0m\u001b[1;34m'JobCard Date'\u001b[0m\u001b[1;33m]\u001b[0m\u001b[1;33m,\u001b[0m\u001b[1;33m\u001b[0m\u001b[1;33m\u001b[0m\u001b[0m\n\u001b[0m\u001b[0;32m      5\u001b[0m                     \u001b[0my\u001b[0m \u001b[1;33m=\u001b[0m \u001b[0mfiltered_df\u001b[0m\u001b[1;33m[\u001b[0m\u001b[1;34m'count'\u001b[0m\u001b[1;33m]\u001b[0m\u001b[1;33m,\u001b[0m\u001b[1;33m\u001b[0m\u001b[1;33m\u001b[0m\u001b[0m\n\u001b[0;32m      6\u001b[0m                     \u001b[0mname\u001b[0m \u001b[1;33m=\u001b[0m \u001b[0mselected_state\u001b[0m\u001b[1;33m,\u001b[0m\u001b[1;33m\u001b[0m\u001b[1;33m\u001b[0m\u001b[0m\n",
      "\u001b[1;31mNameError\u001b[0m: name 'filtered_df' is not defined"
     ]
    }
   ],
   "source": [
    "traces=[]\n",
    "            \n",
    "trace1= go.Scatter(\n",
    "                    x = filtered_df['JobCard Date'],\n",
    "                    y = filtered_df['count'],\n",
    "                    name = selected_state,\n",
    "                  #  mode = 'markers',\n",
    "                    mode='markers',\n",
    "                    #marker = {\n",
    "                        #'size': 12,\n",
    "                       # 'color': 'rgb(51,204,153)',\n",
    "                       #'symbol': 'pentagon',\n",
    "                      #  'line': {'width': 2},\n",
    "                    text=filtered_df['Order Type']\n",
    "                        \n",
    "                )\n",
    "traces.append(trace1)"
   ]
  },
  {
   "cell_type": "code",
   "execution_count": 40,
   "metadata": {
    "collapsed": true
   },
   "outputs": [
    {
     "name": "stdout",
     "output_type": "stream",
     "text": [
      "Dash is running on http://127.0.0.1:8050/\n",
      "\n",
      "Dash is running on http://127.0.0.1:8050/\n",
      "\n",
      "Dash is running on http://127.0.0.1:8050/\n",
      "\n",
      "Dash is running on http://127.0.0.1:8050/\n",
      "\n",
      "Dash is running on http://127.0.0.1:8050/\n",
      "\n",
      "Dash is running on http://127.0.0.1:8050/\n",
      "\n",
      "Dash is running on http://127.0.0.1:8050/\n",
      "\n",
      "Dash is running on http://127.0.0.1:8050/\n",
      "\n",
      "Dash is running on http://127.0.0.1:8050/\n",
      "\n",
      "Dash is running on http://127.0.0.1:8050/\n",
      "\n",
      "Dash is running on http://127.0.0.1:8050/\n",
      "\n",
      "Dash is running on http://127.0.0.1:8050/\n",
      "\n",
      " Warning: This is a development server. Do not use app.run_server\n",
      " Warning: This is a development server. Do not use app.run_server\n",
      " Warning: This is a development server. Do not use app.run_server\n",
      " Warning: This is a development server. Do not use app.run_server\n",
      " Warning: This is a development server. Do not use app.run_server\n",
      " Warning: This is a development server. Do not use app.run_server\n",
      " Warning: This is a development server. Do not use app.run_server\n",
      " Warning: This is a development server. Do not use app.run_server\n",
      " Warning: This is a development server. Do not use app.run_server\n",
      " Warning: This is a development server. Do not use app.run_server\n",
      " Warning: This is a development server. Do not use app.run_server\n",
      " Warning: This is a development server. Do not use app.run_server\n",
      " in production, use a production WSGI server like gunicorn instead.\n",
      "\n",
      " in production, use a production WSGI server like gunicorn instead.\n",
      "\n",
      " in production, use a production WSGI server like gunicorn instead.\n",
      "\n",
      " in production, use a production WSGI server like gunicorn instead.\n",
      "\n",
      " in production, use a production WSGI server like gunicorn instead.\n",
      "\n",
      " in production, use a production WSGI server like gunicorn instead.\n",
      "\n",
      " in production, use a production WSGI server like gunicorn instead.\n",
      "\n",
      " in production, use a production WSGI server like gunicorn instead.\n",
      "\n",
      " in production, use a production WSGI server like gunicorn instead.\n",
      "\n",
      " in production, use a production WSGI server like gunicorn instead.\n",
      "\n",
      " in production, use a production WSGI server like gunicorn instead.\n",
      "\n",
      " in production, use a production WSGI server like gunicorn instead.\n",
      "\n",
      " * Serving Flask app \"__main__\" (lazy loading)\n",
      " * Environment: production\n",
      "   WARNING: This is a development server. Do not use it in a production deployment.\n",
      "   Use a production WSGI server instead.\n",
      " * Debug mode: off\n"
     ]
    },
    {
     "name": "stderr",
     "output_type": "stream",
     "text": [
      " * Running on http://127.0.0.1:8050/ (Press CTRL+C to quit)\n",
      "127.0.0.1 - - [27/Jun/2020 15:18:17] \"\u001b[37mGET / HTTP/1.1\u001b[0m\" 200 -\n",
      "127.0.0.1 - - [27/Jun/2020 15:18:18] \"\u001b[37mGET /_dash-layout HTTP/1.1\u001b[0m\" 200 -\n",
      "127.0.0.1 - - [27/Jun/2020 15:18:18] \"\u001b[37mGET /_dash-dependencies HTTP/1.1\u001b[0m\" 200 -\n"
     ]
    },
    {
     "name": "stdout",
     "output_type": "stream",
     "text": [
      "Exception on /_dash-update-component [POST]\n",
      "Traceback (most recent call last):\n",
      "  File \"C:\\Users\\Fakhruddin\\Anaconda3\\lib\\site-packages\\pandas\\core\\indexes\\base.py\", line 2646, in get_loc\n",
      "    return self._engine.get_loc(key)\n",
      "  File \"pandas\\_libs\\index.pyx\", line 111, in pandas._libs.index.IndexEngine.get_loc\n",
      "  File \"pandas\\_libs\\index.pyx\", line 138, in pandas._libs.index.IndexEngine.get_loc\n",
      "  File \"pandas\\_libs\\hashtable_class_helper.pxi\", line 1619, in pandas._libs.hashtable.PyObjectHashTable.get_item\n",
      "  File \"pandas\\_libs\\hashtable_class_helper.pxi\", line 1627, in pandas._libs.hashtable.PyObjectHashTable.get_item\n",
      "KeyError: 'count'\n",
      "\n",
      "During handling of the above exception, another exception occurred:\n",
      "\n",
      "Traceback (most recent call last):\n",
      "  File \"C:\\Users\\Fakhruddin\\Anaconda3\\lib\\site-packages\\flask\\app.py\", line 2446, in wsgi_app\n",
      "    response = self.full_dispatch_request()\n",
      "  File \"C:\\Users\\Fakhruddin\\Anaconda3\\lib\\site-packages\\flask\\app.py\", line 1951, in full_dispatch_request\n",
      "    rv = self.handle_user_exception(e)\n",
      "  File \"C:\\Users\\Fakhruddin\\Anaconda3\\lib\\site-packages\\flask\\app.py\", line 1820, in handle_user_exception\n",
      "    reraise(exc_type, exc_value, tb)\n",
      "  File \"C:\\Users\\Fakhruddin\\Anaconda3\\lib\\site-packages\\flask\\_compat.py\", line 39, in reraise\n",
      "    raise value\n",
      "  File \"C:\\Users\\Fakhruddin\\Anaconda3\\lib\\site-packages\\flask\\app.py\", line 1949, in full_dispatch_request\n",
      "    rv = self.dispatch_request()\n",
      "  File \"C:\\Users\\Fakhruddin\\Anaconda3\\lib\\site-packages\\flask\\app.py\", line 1935, in dispatch_request\n",
      "    return self.view_functions[rule.endpoint](**req.view_args)\n",
      "  File \"C:\\Users\\Fakhruddin\\Anaconda3\\lib\\site-packages\\dash\\dash.py\", line 1031, in dispatch\n",
      "    response.set_data(func(*args, outputs_list=outputs_list))\n",
      "  File \"C:\\Users\\Fakhruddin\\Anaconda3\\lib\\site-packages\\dash\\dash.py\", line 966, in add_context\n",
      "    output_value = func(*args, **kwargs)  # %% callback invoked %%\n",
      "  File \"<ipython-input-40-963591925d46>\", line 56, in update_graph\n",
      "    y = filtered_df['count'],\n",
      "  File \"C:\\Users\\Fakhruddin\\Anaconda3\\lib\\site-packages\\pandas\\core\\frame.py\", line 2800, in __getitem__\n",
      "    indexer = self.columns.get_loc(key)\n",
      "  File \"C:\\Users\\Fakhruddin\\Anaconda3\\lib\\site-packages\\pandas\\core\\indexes\\base.py\", line 2648, in get_loc\n",
      "    return self._engine.get_loc(self._maybe_cast_indexer(key))\n",
      "  File \"pandas\\_libs\\index.pyx\", line 111, in pandas._libs.index.IndexEngine.get_loc\n",
      "  File \"pandas\\_libs\\index.pyx\", line 138, in pandas._libs.index.IndexEngine.get_loc\n",
      "  File \"pandas\\_libs\\hashtable_class_helper.pxi\", line 1619, in pandas._libs.hashtable.PyObjectHashTable.get_item\n",
      "  File \"pandas\\_libs\\hashtable_class_helper.pxi\", line 1627, in pandas._libs.hashtable.PyObjectHashTable.get_item\n",
      "KeyError: 'count'\n",
      "Exception on /_dash-update-component [POST]\n",
      "Traceback (most recent call last):\n",
      "  File \"C:\\Users\\Fakhruddin\\Anaconda3\\lib\\site-packages\\pandas\\core\\indexes\\base.py\", line 2646, in get_loc\n",
      "    return self._engine.get_loc(key)\n",
      "  File \"pandas\\_libs\\index.pyx\", line 111, in pandas._libs.index.IndexEngine.get_loc\n",
      "  File \"pandas\\_libs\\index.pyx\", line 138, in pandas._libs.index.IndexEngine.get_loc\n",
      "  File \"pandas\\_libs\\hashtable_class_helper.pxi\", line 1619, in pandas._libs.hashtable.PyObjectHashTable.get_item\n",
      "  File \"pandas\\_libs\\hashtable_class_helper.pxi\", line 1627, in pandas._libs.hashtable.PyObjectHashTable.get_item\n",
      "KeyError: 'count'\n",
      "\n",
      "During handling of the above exception, another exception occurred:\n",
      "\n",
      "Traceback (most recent call last):\n",
      "  File \"C:\\Users\\Fakhruddin\\Anaconda3\\lib\\site-packages\\flask\\app.py\", line 2446, in wsgi_app\n",
      "    response = self.full_dispatch_request()\n",
      "  File \"C:\\Users\\Fakhruddin\\Anaconda3\\lib\\site-packages\\flask\\app.py\", line 1951, in full_dispatch_request\n",
      "    rv = self.handle_user_exception(e)\n",
      "  File \"C:\\Users\\Fakhruddin\\Anaconda3\\lib\\site-packages\\flask\\app.py\", line 1820, in handle_user_exception\n",
      "    reraise(exc_type, exc_value, tb)\n",
      "  File \"C:\\Users\\Fakhruddin\\Anaconda3\\lib\\site-packages\\flask\\_compat.py\", line 39, in reraise\n",
      "    raise value\n",
      "  File \"C:\\Users\\Fakhruddin\\Anaconda3\\lib\\site-packages\\flask\\app.py\", line 1949, in full_dispatch_request\n",
      "    rv = self.dispatch_request()\n",
      "  File \"C:\\Users\\Fakhruddin\\Anaconda3\\lib\\site-packages\\flask\\app.py\", line 1935, in dispatch_request\n",
      "    return self.view_functions[rule.endpoint](**req.view_args)\n",
      "  File \"C:\\Users\\Fakhruddin\\Anaconda3\\lib\\site-packages\\dash\\dash.py\", line 1031, in dispatch\n",
      "    response.set_data(func(*args, outputs_list=outputs_list))\n",
      "  File \"C:\\Users\\Fakhruddin\\Anaconda3\\lib\\site-packages\\dash\\dash.py\", line 966, in add_context\n",
      "    output_value = func(*args, **kwargs)  # %% callback invoked %%\n",
      "  File \"<ipython-input-40-963591925d46>\", line 56, in update_graph\n",
      "    y = filtered_df['count'],\n",
      "  File \"C:\\Users\\Fakhruddin\\Anaconda3\\lib\\site-packages\\pandas\\core\\frame.py\", line 2800, in __getitem__\n",
      "    indexer = self.columns.get_loc(key)\n",
      "  File \"C:\\Users\\Fakhruddin\\Anaconda3\\lib\\site-packages\\pandas\\core\\indexes\\base.py\", line 2648, in get_loc\n",
      "    return self._engine.get_loc(self._maybe_cast_indexer(key))\n",
      "  File \"pandas\\_libs\\index.pyx\", line 111, in pandas._libs.index.IndexEngine.get_loc\n",
      "  File \"pandas\\_libs\\index.pyx\", line 138, in pandas._libs.index.IndexEngine.get_loc\n",
      "  File \"pandas\\_libs\\hashtable_class_helper.pxi\", line 1619, in pandas._libs.hashtable.PyObjectHashTable.get_item\n",
      "  File \"pandas\\_libs\\hashtable_class_helper.pxi\", line 1627, in pandas._libs.hashtable.PyObjectHashTable.get_item\n",
      "KeyError: 'count'\n",
      "Exception on /_dash-update-component [POST]\n",
      "Traceback (most recent call last):\n",
      "  File \"C:\\Users\\Fakhruddin\\Anaconda3\\lib\\site-packages\\pandas\\core\\indexes\\base.py\", line 2646, in get_loc\n",
      "    return self._engine.get_loc(key)\n",
      "  File \"pandas\\_libs\\index.pyx\", line 111, in pandas._libs.index.IndexEngine.get_loc\n",
      "  File \"pandas\\_libs\\index.pyx\", line 138, in pandas._libs.index.IndexEngine.get_loc\n",
      "  File \"pandas\\_libs\\hashtable_class_helper.pxi\", line 1619, in pandas._libs.hashtable.PyObjectHashTable.get_item\n",
      "  File \"pandas\\_libs\\hashtable_class_helper.pxi\", line 1627, in pandas._libs.hashtable.PyObjectHashTable.get_item\n",
      "KeyError: 'count'\n",
      "\n",
      "During handling of the above exception, another exception occurred:\n",
      "\n",
      "Traceback (most recent call last):\n",
      "  File \"C:\\Users\\Fakhruddin\\Anaconda3\\lib\\site-packages\\flask\\app.py\", line 2446, in wsgi_app\n",
      "    response = self.full_dispatch_request()\n",
      "  File \"C:\\Users\\Fakhruddin\\Anaconda3\\lib\\site-packages\\flask\\app.py\", line 1951, in full_dispatch_request\n",
      "    rv = self.handle_user_exception(e)\n",
      "  File \"C:\\Users\\Fakhruddin\\Anaconda3\\lib\\site-packages\\flask\\app.py\", line 1820, in handle_user_exception\n",
      "    reraise(exc_type, exc_value, tb)\n",
      "  File \"C:\\Users\\Fakhruddin\\Anaconda3\\lib\\site-packages\\flask\\_compat.py\", line 39, in reraise\n",
      "    raise value\n",
      "  File \"C:\\Users\\Fakhruddin\\Anaconda3\\lib\\site-packages\\flask\\app.py\", line 1949, in full_dispatch_request\n",
      "    rv = self.dispatch_request()\n",
      "  File \"C:\\Users\\Fakhruddin\\Anaconda3\\lib\\site-packages\\flask\\app.py\", line 1935, in dispatch_request\n",
      "    return self.view_functions[rule.endpoint](**req.view_args)\n",
      "  File \"C:\\Users\\Fakhruddin\\Anaconda3\\lib\\site-packages\\dash\\dash.py\", line 1031, in dispatch\n",
      "    response.set_data(func(*args, outputs_list=outputs_list))\n",
      "  File \"C:\\Users\\Fakhruddin\\Anaconda3\\lib\\site-packages\\dash\\dash.py\", line 966, in add_context\n",
      "    output_value = func(*args, **kwargs)  # %% callback invoked %%\n",
      "  File \"<ipython-input-40-963591925d46>\", line 56, in update_graph\n",
      "    y = filtered_df['count'],\n",
      "  File \"C:\\Users\\Fakhruddin\\Anaconda3\\lib\\site-packages\\pandas\\core\\frame.py\", line 2800, in __getitem__\n",
      "    indexer = self.columns.get_loc(key)\n",
      "  File \"C:\\Users\\Fakhruddin\\Anaconda3\\lib\\site-packages\\pandas\\core\\indexes\\base.py\", line 2648, in get_loc\n",
      "    return self._engine.get_loc(self._maybe_cast_indexer(key))\n",
      "  File \"pandas\\_libs\\index.pyx\", line 111, in pandas._libs.index.IndexEngine.get_loc\n",
      "  File \"pandas\\_libs\\index.pyx\", line 138, in pandas._libs.index.IndexEngine.get_loc\n",
      "  File \"pandas\\_libs\\hashtable_class_helper.pxi\", line 1619, in pandas._libs.hashtable.PyObjectHashTable.get_item\n",
      "  File \"pandas\\_libs\\hashtable_class_helper.pxi\", line 1627, in pandas._libs.hashtable.PyObjectHashTable.get_item\n",
      "KeyError: 'count'\n"
     ]
    },
    {
     "name": "stdout",
     "output_type": "stream",
     "text": [
      "Exception on /_dash-update-component [POST]\n",
      "Traceback (most recent call last):\n",
      "  File \"C:\\Users\\Fakhruddin\\Anaconda3\\lib\\site-packages\\pandas\\core\\indexes\\base.py\", line 2646, in get_loc\n",
      "    return self._engine.get_loc(key)\n",
      "  File \"pandas\\_libs\\index.pyx\", line 111, in pandas._libs.index.IndexEngine.get_loc\n",
      "  File \"pandas\\_libs\\index.pyx\", line 138, in pandas._libs.index.IndexEngine.get_loc\n",
      "  File \"pandas\\_libs\\hashtable_class_helper.pxi\", line 1619, in pandas._libs.hashtable.PyObjectHashTable.get_item\n",
      "  File \"pandas\\_libs\\hashtable_class_helper.pxi\", line 1627, in pandas._libs.hashtable.PyObjectHashTable.get_item\n",
      "KeyError: 'count'\n",
      "\n",
      "During handling of the above exception, another exception occurred:\n",
      "\n",
      "Traceback (most recent call last):\n",
      "  File \"C:\\Users\\Fakhruddin\\Anaconda3\\lib\\site-packages\\flask\\app.py\", line 2446, in wsgi_app\n",
      "    response = self.full_dispatch_request()\n",
      "  File \"C:\\Users\\Fakhruddin\\Anaconda3\\lib\\site-packages\\flask\\app.py\", line 1951, in full_dispatch_request\n",
      "    rv = self.handle_user_exception(e)\n",
      "  File \"C:\\Users\\Fakhruddin\\Anaconda3\\lib\\site-packages\\flask\\app.py\", line 1820, in handle_user_exception\n",
      "    reraise(exc_type, exc_value, tb)\n",
      "  File \"C:\\Users\\Fakhruddin\\Anaconda3\\lib\\site-packages\\flask\\_compat.py\", line 39, in reraise\n",
      "    raise value\n",
      "  File \"C:\\Users\\Fakhruddin\\Anaconda3\\lib\\site-packages\\flask\\app.py\", line 1949, in full_dispatch_request\n",
      "    rv = self.dispatch_request()\n",
      "  File \"C:\\Users\\Fakhruddin\\Anaconda3\\lib\\site-packages\\flask\\app.py\", line 1935, in dispatch_request\n",
      "    return self.view_functions[rule.endpoint](**req.view_args)\n",
      "  File \"C:\\Users\\Fakhruddin\\Anaconda3\\lib\\site-packages\\dash\\dash.py\", line 1031, in dispatch\n",
      "    response.set_data(func(*args, outputs_list=outputs_list))\n",
      "  File \"C:\\Users\\Fakhruddin\\Anaconda3\\lib\\site-packages\\dash\\dash.py\", line 966, in add_context\n",
      "    output_value = func(*args, **kwargs)  # %% callback invoked %%\n",
      "  File \"<ipython-input-40-963591925d46>\", line 56, in update_graph\n",
      "    y = filtered_df['count'],\n",
      "  File \"C:\\Users\\Fakhruddin\\Anaconda3\\lib\\site-packages\\pandas\\core\\frame.py\", line 2800, in __getitem__\n",
      "    indexer = self.columns.get_loc(key)\n",
      "  File \"C:\\Users\\Fakhruddin\\Anaconda3\\lib\\site-packages\\pandas\\core\\indexes\\base.py\", line 2648, in get_loc\n",
      "    return self._engine.get_loc(self._maybe_cast_indexer(key))\n",
      "  File \"pandas\\_libs\\index.pyx\", line 111, in pandas._libs.index.IndexEngine.get_loc\n",
      "  File \"pandas\\_libs\\index.pyx\", line 138, in pandas._libs.index.IndexEngine.get_loc\n",
      "  File \"pandas\\_libs\\hashtable_class_helper.pxi\", line 1619, in pandas._libs.hashtable.PyObjectHashTable.get_item\n",
      "  File \"pandas\\_libs\\hashtable_class_helper.pxi\", line 1627, in pandas._libs.hashtable.PyObjectHashTable.get_item\n",
      "KeyError: 'count'\n",
      "Exception on /_dash-update-component [POST]\n",
      "Traceback (most recent call last):\n",
      "  File \"C:\\Users\\Fakhruddin\\Anaconda3\\lib\\site-packages\\pandas\\core\\indexes\\base.py\", line 2646, in get_loc\n",
      "    return self._engine.get_loc(key)\n",
      "  File \"pandas\\_libs\\index.pyx\", line 111, in pandas._libs.index.IndexEngine.get_loc\n",
      "  File \"pandas\\_libs\\index.pyx\", line 138, in pandas._libs.index.IndexEngine.get_loc\n",
      "  File \"pandas\\_libs\\hashtable_class_helper.pxi\", line 1619, in pandas._libs.hashtable.PyObjectHashTable.get_item\n",
      "  File \"pandas\\_libs\\hashtable_class_helper.pxi\", line 1627, in pandas._libs.hashtable.PyObjectHashTable.get_item\n",
      "KeyError: 'count'\n",
      "\n",
      "During handling of the above exception, another exception occurred:\n",
      "\n",
      "Traceback (most recent call last):\n",
      "  File \"C:\\Users\\Fakhruddin\\Anaconda3\\lib\\site-packages\\flask\\app.py\", line 2446, in wsgi_app\n",
      "    response = self.full_dispatch_request()\n",
      "  File \"C:\\Users\\Fakhruddin\\Anaconda3\\lib\\site-packages\\flask\\app.py\", line 1951, in full_dispatch_request\n",
      "    rv = self.handle_user_exception(e)\n",
      "  File \"C:\\Users\\Fakhruddin\\Anaconda3\\lib\\site-packages\\flask\\app.py\", line 1820, in handle_user_exception\n",
      "    reraise(exc_type, exc_value, tb)\n",
      "  File \"C:\\Users\\Fakhruddin\\Anaconda3\\lib\\site-packages\\flask\\_compat.py\", line 39, in reraise\n",
      "    raise value\n",
      "  File \"C:\\Users\\Fakhruddin\\Anaconda3\\lib\\site-packages\\flask\\app.py\", line 1949, in full_dispatch_request\n",
      "    rv = self.dispatch_request()\n",
      "  File \"C:\\Users\\Fakhruddin\\Anaconda3\\lib\\site-packages\\flask\\app.py\", line 1935, in dispatch_request\n",
      "    return self.view_functions[rule.endpoint](**req.view_args)\n",
      "  File \"C:\\Users\\Fakhruddin\\Anaconda3\\lib\\site-packages\\dash\\dash.py\", line 1031, in dispatch\n",
      "    response.set_data(func(*args, outputs_list=outputs_list))\n",
      "  File \"C:\\Users\\Fakhruddin\\Anaconda3\\lib\\site-packages\\dash\\dash.py\", line 966, in add_context\n",
      "    output_value = func(*args, **kwargs)  # %% callback invoked %%\n",
      "  File \"<ipython-input-40-963591925d46>\", line 56, in update_graph\n",
      "    y = filtered_df['count'],\n",
      "  File \"C:\\Users\\Fakhruddin\\Anaconda3\\lib\\site-packages\\pandas\\core\\frame.py\", line 2800, in __getitem__\n",
      "    indexer = self.columns.get_loc(key)\n",
      "  File \"C:\\Users\\Fakhruddin\\Anaconda3\\lib\\site-packages\\pandas\\core\\indexes\\base.py\", line 2648, in get_loc\n",
      "    return self._engine.get_loc(self._maybe_cast_indexer(key))\n",
      "  File \"pandas\\_libs\\index.pyx\", line 111, in pandas._libs.index.IndexEngine.get_loc\n",
      "  File \"pandas\\_libs\\index.pyx\", line 138, in pandas._libs.index.IndexEngine.get_loc\n",
      "  File \"pandas\\_libs\\hashtable_class_helper.pxi\", line 1619, in pandas._libs.hashtable.PyObjectHashTable.get_item\n",
      "  File \"pandas\\_libs\\hashtable_class_helper.pxi\", line 1627, in pandas._libs.hashtable.PyObjectHashTable.get_item\n",
      "KeyError: 'count'\n",
      "Exception on /_dash-update-component [POST]\n",
      "Traceback (most recent call last):\n",
      "  File \"C:\\Users\\Fakhruddin\\Anaconda3\\lib\\site-packages\\pandas\\core\\indexes\\base.py\", line 2646, in get_loc\n",
      "    return self._engine.get_loc(key)\n",
      "  File \"pandas\\_libs\\index.pyx\", line 111, in pandas._libs.index.IndexEngine.get_loc\n",
      "  File \"pandas\\_libs\\index.pyx\", line 138, in pandas._libs.index.IndexEngine.get_loc\n",
      "  File \"pandas\\_libs\\hashtable_class_helper.pxi\", line 1619, in pandas._libs.hashtable.PyObjectHashTable.get_item\n",
      "  File \"pandas\\_libs\\hashtable_class_helper.pxi\", line 1627, in pandas._libs.hashtable.PyObjectHashTable.get_item\n",
      "KeyError: 'count'\n",
      "\n",
      "During handling of the above exception, another exception occurred:\n",
      "\n",
      "Traceback (most recent call last):\n",
      "  File \"C:\\Users\\Fakhruddin\\Anaconda3\\lib\\site-packages\\flask\\app.py\", line 2446, in wsgi_app\n",
      "    response = self.full_dispatch_request()\n",
      "  File \"C:\\Users\\Fakhruddin\\Anaconda3\\lib\\site-packages\\flask\\app.py\", line 1951, in full_dispatch_request\n",
      "    rv = self.handle_user_exception(e)\n",
      "  File \"C:\\Users\\Fakhruddin\\Anaconda3\\lib\\site-packages\\flask\\app.py\", line 1820, in handle_user_exception\n",
      "    reraise(exc_type, exc_value, tb)\n",
      "  File \"C:\\Users\\Fakhruddin\\Anaconda3\\lib\\site-packages\\flask\\_compat.py\", line 39, in reraise\n",
      "    raise value\n",
      "  File \"C:\\Users\\Fakhruddin\\Anaconda3\\lib\\site-packages\\flask\\app.py\", line 1949, in full_dispatch_request\n",
      "    rv = self.dispatch_request()\n",
      "  File \"C:\\Users\\Fakhruddin\\Anaconda3\\lib\\site-packages\\flask\\app.py\", line 1935, in dispatch_request\n",
      "    return self.view_functions[rule.endpoint](**req.view_args)\n",
      "  File \"C:\\Users\\Fakhruddin\\Anaconda3\\lib\\site-packages\\dash\\dash.py\", line 1031, in dispatch\n",
      "    response.set_data(func(*args, outputs_list=outputs_list))\n",
      "  File \"C:\\Users\\Fakhruddin\\Anaconda3\\lib\\site-packages\\dash\\dash.py\", line 966, in add_context\n",
      "    output_value = func(*args, **kwargs)  # %% callback invoked %%\n",
      "  File \"<ipython-input-40-963591925d46>\", line 56, in update_graph\n",
      "    y = filtered_df['count'],\n",
      "  File \"C:\\Users\\Fakhruddin\\Anaconda3\\lib\\site-packages\\pandas\\core\\frame.py\", line 2800, in __getitem__\n",
      "    indexer = self.columns.get_loc(key)\n",
      "  File \"C:\\Users\\Fakhruddin\\Anaconda3\\lib\\site-packages\\pandas\\core\\indexes\\base.py\", line 2648, in get_loc\n",
      "    return self._engine.get_loc(self._maybe_cast_indexer(key))\n",
      "  File \"pandas\\_libs\\index.pyx\", line 111, in pandas._libs.index.IndexEngine.get_loc\n",
      "  File \"pandas\\_libs\\index.pyx\", line 138, in pandas._libs.index.IndexEngine.get_loc\n",
      "  File \"pandas\\_libs\\hashtable_class_helper.pxi\", line 1619, in pandas._libs.hashtable.PyObjectHashTable.get_item\n",
      "  File \"pandas\\_libs\\hashtable_class_helper.pxi\", line 1627, in pandas._libs.hashtable.PyObjectHashTable.get_item\n",
      "KeyError: 'count'\n"
     ]
    },
    {
     "name": "stdout",
     "output_type": "stream",
     "text": [
      "Exception on /_dash-update-component [POST]\n",
      "Traceback (most recent call last):\n",
      "  File \"C:\\Users\\Fakhruddin\\Anaconda3\\lib\\site-packages\\pandas\\core\\indexes\\base.py\", line 2646, in get_loc\n",
      "    return self._engine.get_loc(key)\n",
      "  File \"pandas\\_libs\\index.pyx\", line 111, in pandas._libs.index.IndexEngine.get_loc\n",
      "  File \"pandas\\_libs\\index.pyx\", line 138, in pandas._libs.index.IndexEngine.get_loc\n",
      "  File \"pandas\\_libs\\hashtable_class_helper.pxi\", line 1619, in pandas._libs.hashtable.PyObjectHashTable.get_item\n",
      "  File \"pandas\\_libs\\hashtable_class_helper.pxi\", line 1627, in pandas._libs.hashtable.PyObjectHashTable.get_item\n",
      "KeyError: 'count'\n",
      "\n",
      "During handling of the above exception, another exception occurred:\n",
      "\n",
      "Traceback (most recent call last):\n",
      "  File \"C:\\Users\\Fakhruddin\\Anaconda3\\lib\\site-packages\\flask\\app.py\", line 2446, in wsgi_app\n",
      "    response = self.full_dispatch_request()\n",
      "  File \"C:\\Users\\Fakhruddin\\Anaconda3\\lib\\site-packages\\flask\\app.py\", line 1951, in full_dispatch_request\n",
      "    rv = self.handle_user_exception(e)\n",
      "  File \"C:\\Users\\Fakhruddin\\Anaconda3\\lib\\site-packages\\flask\\app.py\", line 1820, in handle_user_exception\n",
      "    reraise(exc_type, exc_value, tb)\n",
      "  File \"C:\\Users\\Fakhruddin\\Anaconda3\\lib\\site-packages\\flask\\_compat.py\", line 39, in reraise\n",
      "    raise value\n",
      "  File \"C:\\Users\\Fakhruddin\\Anaconda3\\lib\\site-packages\\flask\\app.py\", line 1949, in full_dispatch_request\n",
      "    rv = self.dispatch_request()\n",
      "  File \"C:\\Users\\Fakhruddin\\Anaconda3\\lib\\site-packages\\flask\\app.py\", line 1935, in dispatch_request\n",
      "    return self.view_functions[rule.endpoint](**req.view_args)\n",
      "  File \"C:\\Users\\Fakhruddin\\Anaconda3\\lib\\site-packages\\dash\\dash.py\", line 1031, in dispatch\n",
      "    response.set_data(func(*args, outputs_list=outputs_list))\n",
      "  File \"C:\\Users\\Fakhruddin\\Anaconda3\\lib\\site-packages\\dash\\dash.py\", line 966, in add_context\n",
      "    output_value = func(*args, **kwargs)  # %% callback invoked %%\n",
      "  File \"<ipython-input-40-963591925d46>\", line 56, in update_graph\n",
      "    y = filtered_df['count'],\n",
      "  File \"C:\\Users\\Fakhruddin\\Anaconda3\\lib\\site-packages\\pandas\\core\\frame.py\", line 2800, in __getitem__\n",
      "    indexer = self.columns.get_loc(key)\n",
      "  File \"C:\\Users\\Fakhruddin\\Anaconda3\\lib\\site-packages\\pandas\\core\\indexes\\base.py\", line 2648, in get_loc\n",
      "    return self._engine.get_loc(self._maybe_cast_indexer(key))\n",
      "  File \"pandas\\_libs\\index.pyx\", line 111, in pandas._libs.index.IndexEngine.get_loc\n",
      "  File \"pandas\\_libs\\index.pyx\", line 138, in pandas._libs.index.IndexEngine.get_loc\n",
      "  File \"pandas\\_libs\\hashtable_class_helper.pxi\", line 1619, in pandas._libs.hashtable.PyObjectHashTable.get_item\n",
      "  File \"pandas\\_libs\\hashtable_class_helper.pxi\", line 1627, in pandas._libs.hashtable.PyObjectHashTable.get_item\n",
      "KeyError: 'count'\n",
      "Exception on /_dash-update-component [POST]\n",
      "Traceback (most recent call last):\n",
      "  File \"C:\\Users\\Fakhruddin\\Anaconda3\\lib\\site-packages\\pandas\\core\\indexes\\base.py\", line 2646, in get_loc\n",
      "    return self._engine.get_loc(key)\n",
      "  File \"pandas\\_libs\\index.pyx\", line 111, in pandas._libs.index.IndexEngine.get_loc\n",
      "  File \"pandas\\_libs\\index.pyx\", line 138, in pandas._libs.index.IndexEngine.get_loc\n",
      "  File \"pandas\\_libs\\hashtable_class_helper.pxi\", line 1619, in pandas._libs.hashtable.PyObjectHashTable.get_item\n",
      "  File \"pandas\\_libs\\hashtable_class_helper.pxi\", line 1627, in pandas._libs.hashtable.PyObjectHashTable.get_item\n",
      "KeyError: 'count'\n",
      "\n",
      "During handling of the above exception, another exception occurred:\n",
      "\n",
      "Traceback (most recent call last):\n",
      "  File \"C:\\Users\\Fakhruddin\\Anaconda3\\lib\\site-packages\\flask\\app.py\", line 2446, in wsgi_app\n",
      "    response = self.full_dispatch_request()\n",
      "  File \"C:\\Users\\Fakhruddin\\Anaconda3\\lib\\site-packages\\flask\\app.py\", line 1951, in full_dispatch_request\n",
      "    rv = self.handle_user_exception(e)\n",
      "  File \"C:\\Users\\Fakhruddin\\Anaconda3\\lib\\site-packages\\flask\\app.py\", line 1820, in handle_user_exception\n",
      "    reraise(exc_type, exc_value, tb)\n",
      "  File \"C:\\Users\\Fakhruddin\\Anaconda3\\lib\\site-packages\\flask\\_compat.py\", line 39, in reraise\n",
      "    raise value\n",
      "  File \"C:\\Users\\Fakhruddin\\Anaconda3\\lib\\site-packages\\flask\\app.py\", line 1949, in full_dispatch_request\n",
      "    rv = self.dispatch_request()\n",
      "  File \"C:\\Users\\Fakhruddin\\Anaconda3\\lib\\site-packages\\flask\\app.py\", line 1935, in dispatch_request\n",
      "    return self.view_functions[rule.endpoint](**req.view_args)\n",
      "  File \"C:\\Users\\Fakhruddin\\Anaconda3\\lib\\site-packages\\dash\\dash.py\", line 1031, in dispatch\n",
      "    response.set_data(func(*args, outputs_list=outputs_list))\n",
      "  File \"C:\\Users\\Fakhruddin\\Anaconda3\\lib\\site-packages\\dash\\dash.py\", line 966, in add_context\n",
      "    output_value = func(*args, **kwargs)  # %% callback invoked %%\n",
      "  File \"<ipython-input-40-963591925d46>\", line 56, in update_graph\n",
      "    y = filtered_df['count'],\n",
      "  File \"C:\\Users\\Fakhruddin\\Anaconda3\\lib\\site-packages\\pandas\\core\\frame.py\", line 2800, in __getitem__\n",
      "    indexer = self.columns.get_loc(key)\n",
      "  File \"C:\\Users\\Fakhruddin\\Anaconda3\\lib\\site-packages\\pandas\\core\\indexes\\base.py\", line 2648, in get_loc\n",
      "    return self._engine.get_loc(self._maybe_cast_indexer(key))\n",
      "  File \"pandas\\_libs\\index.pyx\", line 111, in pandas._libs.index.IndexEngine.get_loc\n",
      "  File \"pandas\\_libs\\index.pyx\", line 138, in pandas._libs.index.IndexEngine.get_loc\n",
      "  File \"pandas\\_libs\\hashtable_class_helper.pxi\", line 1619, in pandas._libs.hashtable.PyObjectHashTable.get_item\n",
      "  File \"pandas\\_libs\\hashtable_class_helper.pxi\", line 1627, in pandas._libs.hashtable.PyObjectHashTable.get_item\n",
      "KeyError: 'count'\n",
      "Exception on /_dash-update-component [POST]\n",
      "Traceback (most recent call last):\n",
      "  File \"C:\\Users\\Fakhruddin\\Anaconda3\\lib\\site-packages\\pandas\\core\\indexes\\base.py\", line 2646, in get_loc\n",
      "    return self._engine.get_loc(key)\n",
      "  File \"pandas\\_libs\\index.pyx\", line 111, in pandas._libs.index.IndexEngine.get_loc\n",
      "  File \"pandas\\_libs\\index.pyx\", line 138, in pandas._libs.index.IndexEngine.get_loc\n",
      "  File \"pandas\\_libs\\hashtable_class_helper.pxi\", line 1619, in pandas._libs.hashtable.PyObjectHashTable.get_item\n",
      "  File \"pandas\\_libs\\hashtable_class_helper.pxi\", line 1627, in pandas._libs.hashtable.PyObjectHashTable.get_item\n",
      "KeyError: 'count'\n",
      "\n",
      "During handling of the above exception, another exception occurred:\n",
      "\n",
      "Traceback (most recent call last):\n",
      "  File \"C:\\Users\\Fakhruddin\\Anaconda3\\lib\\site-packages\\flask\\app.py\", line 2446, in wsgi_app\n",
      "    response = self.full_dispatch_request()\n",
      "  File \"C:\\Users\\Fakhruddin\\Anaconda3\\lib\\site-packages\\flask\\app.py\", line 1951, in full_dispatch_request\n",
      "    rv = self.handle_user_exception(e)\n",
      "  File \"C:\\Users\\Fakhruddin\\Anaconda3\\lib\\site-packages\\flask\\app.py\", line 1820, in handle_user_exception\n",
      "    reraise(exc_type, exc_value, tb)\n",
      "  File \"C:\\Users\\Fakhruddin\\Anaconda3\\lib\\site-packages\\flask\\_compat.py\", line 39, in reraise\n",
      "    raise value\n",
      "  File \"C:\\Users\\Fakhruddin\\Anaconda3\\lib\\site-packages\\flask\\app.py\", line 1949, in full_dispatch_request\n",
      "    rv = self.dispatch_request()\n",
      "  File \"C:\\Users\\Fakhruddin\\Anaconda3\\lib\\site-packages\\flask\\app.py\", line 1935, in dispatch_request\n",
      "    return self.view_functions[rule.endpoint](**req.view_args)\n",
      "  File \"C:\\Users\\Fakhruddin\\Anaconda3\\lib\\site-packages\\dash\\dash.py\", line 1031, in dispatch\n",
      "    response.set_data(func(*args, outputs_list=outputs_list))\n",
      "  File \"C:\\Users\\Fakhruddin\\Anaconda3\\lib\\site-packages\\dash\\dash.py\", line 966, in add_context\n",
      "    output_value = func(*args, **kwargs)  # %% callback invoked %%\n",
      "  File \"<ipython-input-40-963591925d46>\", line 56, in update_graph\n",
      "    y = filtered_df['count'],\n",
      "  File \"C:\\Users\\Fakhruddin\\Anaconda3\\lib\\site-packages\\pandas\\core\\frame.py\", line 2800, in __getitem__\n",
      "    indexer = self.columns.get_loc(key)\n",
      "  File \"C:\\Users\\Fakhruddin\\Anaconda3\\lib\\site-packages\\pandas\\core\\indexes\\base.py\", line 2648, in get_loc\n",
      "    return self._engine.get_loc(self._maybe_cast_indexer(key))\n",
      "  File \"pandas\\_libs\\index.pyx\", line 111, in pandas._libs.index.IndexEngine.get_loc\n",
      "  File \"pandas\\_libs\\index.pyx\", line 138, in pandas._libs.index.IndexEngine.get_loc\n",
      "  File \"pandas\\_libs\\hashtable_class_helper.pxi\", line 1619, in pandas._libs.hashtable.PyObjectHashTable.get_item\n",
      "  File \"pandas\\_libs\\hashtable_class_helper.pxi\", line 1627, in pandas._libs.hashtable.PyObjectHashTable.get_item\n",
      "KeyError: 'count'\n"
     ]
    },
    {
     "name": "stdout",
     "output_type": "stream",
     "text": [
      "Exception on /_dash-update-component [POST]\n",
      "Traceback (most recent call last):\n",
      "  File \"C:\\Users\\Fakhruddin\\Anaconda3\\lib\\site-packages\\pandas\\core\\indexes\\base.py\", line 2646, in get_loc\n",
      "    return self._engine.get_loc(key)\n",
      "  File \"pandas\\_libs\\index.pyx\", line 111, in pandas._libs.index.IndexEngine.get_loc\n",
      "  File \"pandas\\_libs\\index.pyx\", line 138, in pandas._libs.index.IndexEngine.get_loc\n",
      "  File \"pandas\\_libs\\hashtable_class_helper.pxi\", line 1619, in pandas._libs.hashtable.PyObjectHashTable.get_item\n",
      "  File \"pandas\\_libs\\hashtable_class_helper.pxi\", line 1627, in pandas._libs.hashtable.PyObjectHashTable.get_item\n",
      "KeyError: 'count'\n",
      "\n",
      "During handling of the above exception, another exception occurred:\n",
      "\n",
      "Traceback (most recent call last):\n",
      "  File \"C:\\Users\\Fakhruddin\\Anaconda3\\lib\\site-packages\\flask\\app.py\", line 2446, in wsgi_app\n",
      "    response = self.full_dispatch_request()\n",
      "  File \"C:\\Users\\Fakhruddin\\Anaconda3\\lib\\site-packages\\flask\\app.py\", line 1951, in full_dispatch_request\n",
      "    rv = self.handle_user_exception(e)\n",
      "  File \"C:\\Users\\Fakhruddin\\Anaconda3\\lib\\site-packages\\flask\\app.py\", line 1820, in handle_user_exception\n",
      "    reraise(exc_type, exc_value, tb)\n",
      "  File \"C:\\Users\\Fakhruddin\\Anaconda3\\lib\\site-packages\\flask\\_compat.py\", line 39, in reraise\n",
      "    raise value\n",
      "  File \"C:\\Users\\Fakhruddin\\Anaconda3\\lib\\site-packages\\flask\\app.py\", line 1949, in full_dispatch_request\n",
      "    rv = self.dispatch_request()\n",
      "  File \"C:\\Users\\Fakhruddin\\Anaconda3\\lib\\site-packages\\flask\\app.py\", line 1935, in dispatch_request\n",
      "    return self.view_functions[rule.endpoint](**req.view_args)\n",
      "  File \"C:\\Users\\Fakhruddin\\Anaconda3\\lib\\site-packages\\dash\\dash.py\", line 1031, in dispatch\n",
      "    response.set_data(func(*args, outputs_list=outputs_list))\n",
      "  File \"C:\\Users\\Fakhruddin\\Anaconda3\\lib\\site-packages\\dash\\dash.py\", line 966, in add_context\n",
      "    output_value = func(*args, **kwargs)  # %% callback invoked %%\n",
      "  File \"<ipython-input-40-963591925d46>\", line 56, in update_graph\n",
      "    y = filtered_df['count'],\n",
      "  File \"C:\\Users\\Fakhruddin\\Anaconda3\\lib\\site-packages\\pandas\\core\\frame.py\", line 2800, in __getitem__\n",
      "    indexer = self.columns.get_loc(key)\n",
      "  File \"C:\\Users\\Fakhruddin\\Anaconda3\\lib\\site-packages\\pandas\\core\\indexes\\base.py\", line 2648, in get_loc\n",
      "    return self._engine.get_loc(self._maybe_cast_indexer(key))\n",
      "  File \"pandas\\_libs\\index.pyx\", line 111, in pandas._libs.index.IndexEngine.get_loc\n",
      "  File \"pandas\\_libs\\index.pyx\", line 138, in pandas._libs.index.IndexEngine.get_loc\n",
      "  File \"pandas\\_libs\\hashtable_class_helper.pxi\", line 1619, in pandas._libs.hashtable.PyObjectHashTable.get_item\n",
      "  File \"pandas\\_libs\\hashtable_class_helper.pxi\", line 1627, in pandas._libs.hashtable.PyObjectHashTable.get_item\n",
      "KeyError: 'count'\n",
      "Exception on /_dash-update-component [POST]\n",
      "Traceback (most recent call last):\n",
      "  File \"C:\\Users\\Fakhruddin\\Anaconda3\\lib\\site-packages\\pandas\\core\\indexes\\base.py\", line 2646, in get_loc\n",
      "    return self._engine.get_loc(key)\n",
      "  File \"pandas\\_libs\\index.pyx\", line 111, in pandas._libs.index.IndexEngine.get_loc\n",
      "  File \"pandas\\_libs\\index.pyx\", line 138, in pandas._libs.index.IndexEngine.get_loc\n",
      "  File \"pandas\\_libs\\hashtable_class_helper.pxi\", line 1619, in pandas._libs.hashtable.PyObjectHashTable.get_item\n",
      "  File \"pandas\\_libs\\hashtable_class_helper.pxi\", line 1627, in pandas._libs.hashtable.PyObjectHashTable.get_item\n",
      "KeyError: 'count'\n",
      "\n",
      "During handling of the above exception, another exception occurred:\n",
      "\n",
      "Traceback (most recent call last):\n",
      "  File \"C:\\Users\\Fakhruddin\\Anaconda3\\lib\\site-packages\\flask\\app.py\", line 2446, in wsgi_app\n",
      "    response = self.full_dispatch_request()\n",
      "  File \"C:\\Users\\Fakhruddin\\Anaconda3\\lib\\site-packages\\flask\\app.py\", line 1951, in full_dispatch_request\n",
      "    rv = self.handle_user_exception(e)\n",
      "  File \"C:\\Users\\Fakhruddin\\Anaconda3\\lib\\site-packages\\flask\\app.py\", line 1820, in handle_user_exception\n",
      "    reraise(exc_type, exc_value, tb)\n",
      "  File \"C:\\Users\\Fakhruddin\\Anaconda3\\lib\\site-packages\\flask\\_compat.py\", line 39, in reraise\n",
      "    raise value\n",
      "  File \"C:\\Users\\Fakhruddin\\Anaconda3\\lib\\site-packages\\flask\\app.py\", line 1949, in full_dispatch_request\n",
      "    rv = self.dispatch_request()\n",
      "  File \"C:\\Users\\Fakhruddin\\Anaconda3\\lib\\site-packages\\flask\\app.py\", line 1935, in dispatch_request\n",
      "    return self.view_functions[rule.endpoint](**req.view_args)\n",
      "  File \"C:\\Users\\Fakhruddin\\Anaconda3\\lib\\site-packages\\dash\\dash.py\", line 1031, in dispatch\n",
      "    response.set_data(func(*args, outputs_list=outputs_list))\n",
      "  File \"C:\\Users\\Fakhruddin\\Anaconda3\\lib\\site-packages\\dash\\dash.py\", line 966, in add_context\n",
      "    output_value = func(*args, **kwargs)  # %% callback invoked %%\n",
      "  File \"<ipython-input-40-963591925d46>\", line 56, in update_graph\n",
      "    y = filtered_df['count'],\n",
      "  File \"C:\\Users\\Fakhruddin\\Anaconda3\\lib\\site-packages\\pandas\\core\\frame.py\", line 2800, in __getitem__\n",
      "    indexer = self.columns.get_loc(key)\n",
      "  File \"C:\\Users\\Fakhruddin\\Anaconda3\\lib\\site-packages\\pandas\\core\\indexes\\base.py\", line 2648, in get_loc\n",
      "    return self._engine.get_loc(self._maybe_cast_indexer(key))\n",
      "  File \"pandas\\_libs\\index.pyx\", line 111, in pandas._libs.index.IndexEngine.get_loc\n",
      "  File \"pandas\\_libs\\index.pyx\", line 138, in pandas._libs.index.IndexEngine.get_loc\n",
      "  File \"pandas\\_libs\\hashtable_class_helper.pxi\", line 1619, in pandas._libs.hashtable.PyObjectHashTable.get_item\n",
      "  File \"pandas\\_libs\\hashtable_class_helper.pxi\", line 1627, in pandas._libs.hashtable.PyObjectHashTable.get_item\n",
      "KeyError: 'count'\n",
      "Exception on /_dash-update-component [POST]\n",
      "Traceback (most recent call last):\n",
      "  File \"C:\\Users\\Fakhruddin\\Anaconda3\\lib\\site-packages\\pandas\\core\\indexes\\base.py\", line 2646, in get_loc\n",
      "    return self._engine.get_loc(key)\n",
      "  File \"pandas\\_libs\\index.pyx\", line 111, in pandas._libs.index.IndexEngine.get_loc\n",
      "  File \"pandas\\_libs\\index.pyx\", line 138, in pandas._libs.index.IndexEngine.get_loc\n",
      "  File \"pandas\\_libs\\hashtable_class_helper.pxi\", line 1619, in pandas._libs.hashtable.PyObjectHashTable.get_item\n",
      "  File \"pandas\\_libs\\hashtable_class_helper.pxi\", line 1627, in pandas._libs.hashtable.PyObjectHashTable.get_item\n",
      "KeyError: 'count'\n",
      "\n",
      "During handling of the above exception, another exception occurred:\n",
      "\n",
      "Traceback (most recent call last):\n",
      "  File \"C:\\Users\\Fakhruddin\\Anaconda3\\lib\\site-packages\\flask\\app.py\", line 2446, in wsgi_app\n",
      "    response = self.full_dispatch_request()\n",
      "  File \"C:\\Users\\Fakhruddin\\Anaconda3\\lib\\site-packages\\flask\\app.py\", line 1951, in full_dispatch_request\n",
      "    rv = self.handle_user_exception(e)\n",
      "  File \"C:\\Users\\Fakhruddin\\Anaconda3\\lib\\site-packages\\flask\\app.py\", line 1820, in handle_user_exception\n",
      "    reraise(exc_type, exc_value, tb)\n",
      "  File \"C:\\Users\\Fakhruddin\\Anaconda3\\lib\\site-packages\\flask\\_compat.py\", line 39, in reraise\n",
      "    raise value\n",
      "  File \"C:\\Users\\Fakhruddin\\Anaconda3\\lib\\site-packages\\flask\\app.py\", line 1949, in full_dispatch_request\n",
      "    rv = self.dispatch_request()\n",
      "  File \"C:\\Users\\Fakhruddin\\Anaconda3\\lib\\site-packages\\flask\\app.py\", line 1935, in dispatch_request\n",
      "    return self.view_functions[rule.endpoint](**req.view_args)\n",
      "  File \"C:\\Users\\Fakhruddin\\Anaconda3\\lib\\site-packages\\dash\\dash.py\", line 1031, in dispatch\n",
      "    response.set_data(func(*args, outputs_list=outputs_list))\n",
      "  File \"C:\\Users\\Fakhruddin\\Anaconda3\\lib\\site-packages\\dash\\dash.py\", line 966, in add_context\n",
      "    output_value = func(*args, **kwargs)  # %% callback invoked %%\n",
      "  File \"<ipython-input-40-963591925d46>\", line 56, in update_graph\n",
      "    y = filtered_df['count'],\n",
      "  File \"C:\\Users\\Fakhruddin\\Anaconda3\\lib\\site-packages\\pandas\\core\\frame.py\", line 2800, in __getitem__\n",
      "    indexer = self.columns.get_loc(key)\n",
      "  File \"C:\\Users\\Fakhruddin\\Anaconda3\\lib\\site-packages\\pandas\\core\\indexes\\base.py\", line 2648, in get_loc\n",
      "    return self._engine.get_loc(self._maybe_cast_indexer(key))\n",
      "  File \"pandas\\_libs\\index.pyx\", line 111, in pandas._libs.index.IndexEngine.get_loc\n",
      "  File \"pandas\\_libs\\index.pyx\", line 138, in pandas._libs.index.IndexEngine.get_loc\n",
      "  File \"pandas\\_libs\\hashtable_class_helper.pxi\", line 1619, in pandas._libs.hashtable.PyObjectHashTable.get_item\n",
      "  File \"pandas\\_libs\\hashtable_class_helper.pxi\", line 1627, in pandas._libs.hashtable.PyObjectHashTable.get_item\n",
      "KeyError: 'count'\n"
     ]
    },
    {
     "name": "stderr",
     "output_type": "stream",
     "text": [
      "127.0.0.1 - - [27/Jun/2020 15:18:18] \"\u001b[1m\u001b[35mPOST /_dash-update-component HTTP/1.1\u001b[0m\" 500 -\n"
     ]
    },
    {
     "name": "stdout",
     "output_type": "stream",
     "text": [
      "Exception on /_dash-update-component [POST]\n",
      "Traceback (most recent call last):\n",
      "  File \"C:\\Users\\Fakhruddin\\Anaconda3\\lib\\site-packages\\pandas\\core\\indexes\\base.py\", line 2646, in get_loc\n",
      "    return self._engine.get_loc(key)\n",
      "  File \"pandas\\_libs\\index.pyx\", line 111, in pandas._libs.index.IndexEngine.get_loc\n",
      "  File \"pandas\\_libs\\index.pyx\", line 138, in pandas._libs.index.IndexEngine.get_loc\n",
      "  File \"pandas\\_libs\\hashtable_class_helper.pxi\", line 1619, in pandas._libs.hashtable.PyObjectHashTable.get_item\n",
      "  File \"pandas\\_libs\\hashtable_class_helper.pxi\", line 1627, in pandas._libs.hashtable.PyObjectHashTable.get_item\n",
      "KeyError: 'count'\n",
      "\n",
      "During handling of the above exception, another exception occurred:\n",
      "\n",
      "Traceback (most recent call last):\n",
      "  File \"C:\\Users\\Fakhruddin\\Anaconda3\\lib\\site-packages\\flask\\app.py\", line 2446, in wsgi_app\n",
      "    response = self.full_dispatch_request()\n",
      "  File \"C:\\Users\\Fakhruddin\\Anaconda3\\lib\\site-packages\\flask\\app.py\", line 1951, in full_dispatch_request\n",
      "    rv = self.handle_user_exception(e)\n",
      "  File \"C:\\Users\\Fakhruddin\\Anaconda3\\lib\\site-packages\\flask\\app.py\", line 1820, in handle_user_exception\n",
      "    reraise(exc_type, exc_value, tb)\n",
      "  File \"C:\\Users\\Fakhruddin\\Anaconda3\\lib\\site-packages\\flask\\_compat.py\", line 39, in reraise\n",
      "    raise value\n",
      "  File \"C:\\Users\\Fakhruddin\\Anaconda3\\lib\\site-packages\\flask\\app.py\", line 1949, in full_dispatch_request\n",
      "    rv = self.dispatch_request()\n",
      "  File \"C:\\Users\\Fakhruddin\\Anaconda3\\lib\\site-packages\\flask\\app.py\", line 1935, in dispatch_request\n",
      "    return self.view_functions[rule.endpoint](**req.view_args)\n",
      "  File \"C:\\Users\\Fakhruddin\\Anaconda3\\lib\\site-packages\\dash\\dash.py\", line 1031, in dispatch\n",
      "    response.set_data(func(*args, outputs_list=outputs_list))\n",
      "  File \"C:\\Users\\Fakhruddin\\Anaconda3\\lib\\site-packages\\dash\\dash.py\", line 966, in add_context\n",
      "    output_value = func(*args, **kwargs)  # %% callback invoked %%\n",
      "  File \"<ipython-input-40-963591925d46>\", line 56, in update_graph\n",
      "    y = filtered_df['count'],\n",
      "  File \"C:\\Users\\Fakhruddin\\Anaconda3\\lib\\site-packages\\pandas\\core\\frame.py\", line 2800, in __getitem__\n",
      "    indexer = self.columns.get_loc(key)\n",
      "  File \"C:\\Users\\Fakhruddin\\Anaconda3\\lib\\site-packages\\pandas\\core\\indexes\\base.py\", line 2648, in get_loc\n",
      "    return self._engine.get_loc(self._maybe_cast_indexer(key))\n",
      "  File \"pandas\\_libs\\index.pyx\", line 111, in pandas._libs.index.IndexEngine.get_loc\n",
      "  File \"pandas\\_libs\\index.pyx\", line 138, in pandas._libs.index.IndexEngine.get_loc\n",
      "  File \"pandas\\_libs\\hashtable_class_helper.pxi\", line 1619, in pandas._libs.hashtable.PyObjectHashTable.get_item\n",
      "  File \"pandas\\_libs\\hashtable_class_helper.pxi\", line 1627, in pandas._libs.hashtable.PyObjectHashTable.get_item\n",
      "KeyError: 'count'\n",
      "Exception on /_dash-update-component [POST]\n",
      "Traceback (most recent call last):\n",
      "  File \"C:\\Users\\Fakhruddin\\Anaconda3\\lib\\site-packages\\pandas\\core\\indexes\\base.py\", line 2646, in get_loc\n",
      "    return self._engine.get_loc(key)\n",
      "  File \"pandas\\_libs\\index.pyx\", line 111, in pandas._libs.index.IndexEngine.get_loc\n",
      "  File \"pandas\\_libs\\index.pyx\", line 138, in pandas._libs.index.IndexEngine.get_loc\n",
      "  File \"pandas\\_libs\\hashtable_class_helper.pxi\", line 1619, in pandas._libs.hashtable.PyObjectHashTable.get_item\n",
      "  File \"pandas\\_libs\\hashtable_class_helper.pxi\", line 1627, in pandas._libs.hashtable.PyObjectHashTable.get_item\n",
      "KeyError: 'count'\n",
      "\n",
      "During handling of the above exception, another exception occurred:\n",
      "\n",
      "Traceback (most recent call last):\n",
      "  File \"C:\\Users\\Fakhruddin\\Anaconda3\\lib\\site-packages\\flask\\app.py\", line 2446, in wsgi_app\n",
      "    response = self.full_dispatch_request()\n",
      "  File \"C:\\Users\\Fakhruddin\\Anaconda3\\lib\\site-packages\\flask\\app.py\", line 1951, in full_dispatch_request\n",
      "    rv = self.handle_user_exception(e)\n",
      "  File \"C:\\Users\\Fakhruddin\\Anaconda3\\lib\\site-packages\\flask\\app.py\", line 1820, in handle_user_exception\n",
      "    reraise(exc_type, exc_value, tb)\n",
      "  File \"C:\\Users\\Fakhruddin\\Anaconda3\\lib\\site-packages\\flask\\_compat.py\", line 39, in reraise\n",
      "    raise value\n",
      "  File \"C:\\Users\\Fakhruddin\\Anaconda3\\lib\\site-packages\\flask\\app.py\", line 1949, in full_dispatch_request\n",
      "    rv = self.dispatch_request()\n",
      "  File \"C:\\Users\\Fakhruddin\\Anaconda3\\lib\\site-packages\\flask\\app.py\", line 1935, in dispatch_request\n",
      "    return self.view_functions[rule.endpoint](**req.view_args)\n",
      "  File \"C:\\Users\\Fakhruddin\\Anaconda3\\lib\\site-packages\\dash\\dash.py\", line 1031, in dispatch\n",
      "    response.set_data(func(*args, outputs_list=outputs_list))\n",
      "  File \"C:\\Users\\Fakhruddin\\Anaconda3\\lib\\site-packages\\dash\\dash.py\", line 966, in add_context\n",
      "    output_value = func(*args, **kwargs)  # %% callback invoked %%\n",
      "  File \"<ipython-input-40-963591925d46>\", line 56, in update_graph\n",
      "    y = filtered_df['count'],\n",
      "  File \"C:\\Users\\Fakhruddin\\Anaconda3\\lib\\site-packages\\pandas\\core\\frame.py\", line 2800, in __getitem__\n",
      "    indexer = self.columns.get_loc(key)\n",
      "  File \"C:\\Users\\Fakhruddin\\Anaconda3\\lib\\site-packages\\pandas\\core\\indexes\\base.py\", line 2648, in get_loc\n",
      "    return self._engine.get_loc(self._maybe_cast_indexer(key))\n",
      "  File \"pandas\\_libs\\index.pyx\", line 111, in pandas._libs.index.IndexEngine.get_loc\n",
      "  File \"pandas\\_libs\\index.pyx\", line 138, in pandas._libs.index.IndexEngine.get_loc\n",
      "  File \"pandas\\_libs\\hashtable_class_helper.pxi\", line 1619, in pandas._libs.hashtable.PyObjectHashTable.get_item\n",
      "  File \"pandas\\_libs\\hashtable_class_helper.pxi\", line 1627, in pandas._libs.hashtable.PyObjectHashTable.get_item\n",
      "KeyError: 'count'\n",
      "Exception on /_dash-update-component [POST]\n",
      "Traceback (most recent call last):\n",
      "  File \"C:\\Users\\Fakhruddin\\Anaconda3\\lib\\site-packages\\pandas\\core\\indexes\\base.py\", line 2646, in get_loc\n",
      "    return self._engine.get_loc(key)\n",
      "  File \"pandas\\_libs\\index.pyx\", line 111, in pandas._libs.index.IndexEngine.get_loc\n",
      "  File \"pandas\\_libs\\index.pyx\", line 138, in pandas._libs.index.IndexEngine.get_loc\n",
      "  File \"pandas\\_libs\\hashtable_class_helper.pxi\", line 1619, in pandas._libs.hashtable.PyObjectHashTable.get_item\n",
      "  File \"pandas\\_libs\\hashtable_class_helper.pxi\", line 1627, in pandas._libs.hashtable.PyObjectHashTable.get_item\n",
      "KeyError: 'count'\n",
      "\n",
      "During handling of the above exception, another exception occurred:\n",
      "\n",
      "Traceback (most recent call last):\n",
      "  File \"C:\\Users\\Fakhruddin\\Anaconda3\\lib\\site-packages\\flask\\app.py\", line 2446, in wsgi_app\n",
      "    response = self.full_dispatch_request()\n",
      "  File \"C:\\Users\\Fakhruddin\\Anaconda3\\lib\\site-packages\\flask\\app.py\", line 1951, in full_dispatch_request\n",
      "    rv = self.handle_user_exception(e)\n",
      "  File \"C:\\Users\\Fakhruddin\\Anaconda3\\lib\\site-packages\\flask\\app.py\", line 1820, in handle_user_exception\n",
      "    reraise(exc_type, exc_value, tb)\n",
      "  File \"C:\\Users\\Fakhruddin\\Anaconda3\\lib\\site-packages\\flask\\_compat.py\", line 39, in reraise\n",
      "    raise value\n",
      "  File \"C:\\Users\\Fakhruddin\\Anaconda3\\lib\\site-packages\\flask\\app.py\", line 1949, in full_dispatch_request\n",
      "    rv = self.dispatch_request()\n",
      "  File \"C:\\Users\\Fakhruddin\\Anaconda3\\lib\\site-packages\\flask\\app.py\", line 1935, in dispatch_request\n",
      "    return self.view_functions[rule.endpoint](**req.view_args)\n",
      "  File \"C:\\Users\\Fakhruddin\\Anaconda3\\lib\\site-packages\\dash\\dash.py\", line 1031, in dispatch\n",
      "    response.set_data(func(*args, outputs_list=outputs_list))\n",
      "  File \"C:\\Users\\Fakhruddin\\Anaconda3\\lib\\site-packages\\dash\\dash.py\", line 966, in add_context\n",
      "    output_value = func(*args, **kwargs)  # %% callback invoked %%\n",
      "  File \"<ipython-input-40-963591925d46>\", line 56, in update_graph\n",
      "    y = filtered_df['count'],\n",
      "  File \"C:\\Users\\Fakhruddin\\Anaconda3\\lib\\site-packages\\pandas\\core\\frame.py\", line 2800, in __getitem__\n",
      "    indexer = self.columns.get_loc(key)\n",
      "  File \"C:\\Users\\Fakhruddin\\Anaconda3\\lib\\site-packages\\pandas\\core\\indexes\\base.py\", line 2648, in get_loc\n",
      "    return self._engine.get_loc(self._maybe_cast_indexer(key))\n",
      "  File \"pandas\\_libs\\index.pyx\", line 111, in pandas._libs.index.IndexEngine.get_loc\n",
      "  File \"pandas\\_libs\\index.pyx\", line 138, in pandas._libs.index.IndexEngine.get_loc\n",
      "  File \"pandas\\_libs\\hashtable_class_helper.pxi\", line 1619, in pandas._libs.hashtable.PyObjectHashTable.get_item\n",
      "  File \"pandas\\_libs\\hashtable_class_helper.pxi\", line 1627, in pandas._libs.hashtable.PyObjectHashTable.get_item\n",
      "KeyError: 'count'\n"
     ]
    },
    {
     "name": "stdout",
     "output_type": "stream",
     "text": [
      "Exception on /_dash-update-component [POST]\n",
      "Traceback (most recent call last):\n",
      "  File \"C:\\Users\\Fakhruddin\\Anaconda3\\lib\\site-packages\\pandas\\core\\indexes\\base.py\", line 2646, in get_loc\n",
      "    return self._engine.get_loc(key)\n",
      "  File \"pandas\\_libs\\index.pyx\", line 111, in pandas._libs.index.IndexEngine.get_loc\n",
      "  File \"pandas\\_libs\\index.pyx\", line 138, in pandas._libs.index.IndexEngine.get_loc\n",
      "  File \"pandas\\_libs\\hashtable_class_helper.pxi\", line 1619, in pandas._libs.hashtable.PyObjectHashTable.get_item\n",
      "  File \"pandas\\_libs\\hashtable_class_helper.pxi\", line 1627, in pandas._libs.hashtable.PyObjectHashTable.get_item\n",
      "KeyError: 'count'\n",
      "\n",
      "During handling of the above exception, another exception occurred:\n",
      "\n",
      "Traceback (most recent call last):\n",
      "  File \"C:\\Users\\Fakhruddin\\Anaconda3\\lib\\site-packages\\flask\\app.py\", line 2446, in wsgi_app\n",
      "    response = self.full_dispatch_request()\n",
      "  File \"C:\\Users\\Fakhruddin\\Anaconda3\\lib\\site-packages\\flask\\app.py\", line 1951, in full_dispatch_request\n",
      "    rv = self.handle_user_exception(e)\n",
      "  File \"C:\\Users\\Fakhruddin\\Anaconda3\\lib\\site-packages\\flask\\app.py\", line 1820, in handle_user_exception\n",
      "    reraise(exc_type, exc_value, tb)\n",
      "  File \"C:\\Users\\Fakhruddin\\Anaconda3\\lib\\site-packages\\flask\\_compat.py\", line 39, in reraise\n",
      "    raise value\n",
      "  File \"C:\\Users\\Fakhruddin\\Anaconda3\\lib\\site-packages\\flask\\app.py\", line 1949, in full_dispatch_request\n",
      "    rv = self.dispatch_request()\n",
      "  File \"C:\\Users\\Fakhruddin\\Anaconda3\\lib\\site-packages\\flask\\app.py\", line 1935, in dispatch_request\n",
      "    return self.view_functions[rule.endpoint](**req.view_args)\n",
      "  File \"C:\\Users\\Fakhruddin\\Anaconda3\\lib\\site-packages\\dash\\dash.py\", line 1031, in dispatch\n",
      "    response.set_data(func(*args, outputs_list=outputs_list))\n",
      "  File \"C:\\Users\\Fakhruddin\\Anaconda3\\lib\\site-packages\\dash\\dash.py\", line 966, in add_context\n",
      "    output_value = func(*args, **kwargs)  # %% callback invoked %%\n",
      "  File \"<ipython-input-40-963591925d46>\", line 56, in update_graph\n",
      "    y = filtered_df['count'],\n",
      "  File \"C:\\Users\\Fakhruddin\\Anaconda3\\lib\\site-packages\\pandas\\core\\frame.py\", line 2800, in __getitem__\n",
      "    indexer = self.columns.get_loc(key)\n",
      "  File \"C:\\Users\\Fakhruddin\\Anaconda3\\lib\\site-packages\\pandas\\core\\indexes\\base.py\", line 2648, in get_loc\n",
      "    return self._engine.get_loc(self._maybe_cast_indexer(key))\n",
      "  File \"pandas\\_libs\\index.pyx\", line 111, in pandas._libs.index.IndexEngine.get_loc\n",
      "  File \"pandas\\_libs\\index.pyx\", line 138, in pandas._libs.index.IndexEngine.get_loc\n",
      "  File \"pandas\\_libs\\hashtable_class_helper.pxi\", line 1619, in pandas._libs.hashtable.PyObjectHashTable.get_item\n",
      "  File \"pandas\\_libs\\hashtable_class_helper.pxi\", line 1627, in pandas._libs.hashtable.PyObjectHashTable.get_item\n",
      "KeyError: 'count'\n",
      "Exception on /_dash-update-component [POST]\n",
      "Traceback (most recent call last):\n",
      "  File \"C:\\Users\\Fakhruddin\\Anaconda3\\lib\\site-packages\\pandas\\core\\indexes\\base.py\", line 2646, in get_loc\n",
      "    return self._engine.get_loc(key)\n",
      "  File \"pandas\\_libs\\index.pyx\", line 111, in pandas._libs.index.IndexEngine.get_loc\n",
      "  File \"pandas\\_libs\\index.pyx\", line 138, in pandas._libs.index.IndexEngine.get_loc\n",
      "  File \"pandas\\_libs\\hashtable_class_helper.pxi\", line 1619, in pandas._libs.hashtable.PyObjectHashTable.get_item\n",
      "  File \"pandas\\_libs\\hashtable_class_helper.pxi\", line 1627, in pandas._libs.hashtable.PyObjectHashTable.get_item\n",
      "KeyError: 'count'\n",
      "\n",
      "During handling of the above exception, another exception occurred:\n",
      "\n",
      "Traceback (most recent call last):\n",
      "  File \"C:\\Users\\Fakhruddin\\Anaconda3\\lib\\site-packages\\flask\\app.py\", line 2446, in wsgi_app\n",
      "    response = self.full_dispatch_request()\n",
      "  File \"C:\\Users\\Fakhruddin\\Anaconda3\\lib\\site-packages\\flask\\app.py\", line 1951, in full_dispatch_request\n",
      "    rv = self.handle_user_exception(e)\n",
      "  File \"C:\\Users\\Fakhruddin\\Anaconda3\\lib\\site-packages\\flask\\app.py\", line 1820, in handle_user_exception\n",
      "    reraise(exc_type, exc_value, tb)\n",
      "  File \"C:\\Users\\Fakhruddin\\Anaconda3\\lib\\site-packages\\flask\\_compat.py\", line 39, in reraise\n",
      "    raise value\n",
      "  File \"C:\\Users\\Fakhruddin\\Anaconda3\\lib\\site-packages\\flask\\app.py\", line 1949, in full_dispatch_request\n",
      "    rv = self.dispatch_request()\n",
      "  File \"C:\\Users\\Fakhruddin\\Anaconda3\\lib\\site-packages\\flask\\app.py\", line 1935, in dispatch_request\n",
      "    return self.view_functions[rule.endpoint](**req.view_args)\n",
      "  File \"C:\\Users\\Fakhruddin\\Anaconda3\\lib\\site-packages\\dash\\dash.py\", line 1031, in dispatch\n",
      "    response.set_data(func(*args, outputs_list=outputs_list))\n",
      "  File \"C:\\Users\\Fakhruddin\\Anaconda3\\lib\\site-packages\\dash\\dash.py\", line 966, in add_context\n",
      "    output_value = func(*args, **kwargs)  # %% callback invoked %%\n",
      "  File \"<ipython-input-40-963591925d46>\", line 56, in update_graph\n",
      "    y = filtered_df['count'],\n",
      "  File \"C:\\Users\\Fakhruddin\\Anaconda3\\lib\\site-packages\\pandas\\core\\frame.py\", line 2800, in __getitem__\n",
      "    indexer = self.columns.get_loc(key)\n",
      "  File \"C:\\Users\\Fakhruddin\\Anaconda3\\lib\\site-packages\\pandas\\core\\indexes\\base.py\", line 2648, in get_loc\n",
      "    return self._engine.get_loc(self._maybe_cast_indexer(key))\n",
      "  File \"pandas\\_libs\\index.pyx\", line 111, in pandas._libs.index.IndexEngine.get_loc\n",
      "  File \"pandas\\_libs\\index.pyx\", line 138, in pandas._libs.index.IndexEngine.get_loc\n",
      "  File \"pandas\\_libs\\hashtable_class_helper.pxi\", line 1619, in pandas._libs.hashtable.PyObjectHashTable.get_item\n",
      "  File \"pandas\\_libs\\hashtable_class_helper.pxi\", line 1627, in pandas._libs.hashtable.PyObjectHashTable.get_item\n",
      "KeyError: 'count'\n",
      "Exception on /_dash-update-component [POST]\n",
      "Traceback (most recent call last):\n",
      "  File \"C:\\Users\\Fakhruddin\\Anaconda3\\lib\\site-packages\\pandas\\core\\indexes\\base.py\", line 2646, in get_loc\n",
      "    return self._engine.get_loc(key)\n",
      "  File \"pandas\\_libs\\index.pyx\", line 111, in pandas._libs.index.IndexEngine.get_loc\n",
      "  File \"pandas\\_libs\\index.pyx\", line 138, in pandas._libs.index.IndexEngine.get_loc\n",
      "  File \"pandas\\_libs\\hashtable_class_helper.pxi\", line 1619, in pandas._libs.hashtable.PyObjectHashTable.get_item\n",
      "  File \"pandas\\_libs\\hashtable_class_helper.pxi\", line 1627, in pandas._libs.hashtable.PyObjectHashTable.get_item\n",
      "KeyError: 'count'\n",
      "\n",
      "During handling of the above exception, another exception occurred:\n",
      "\n",
      "Traceback (most recent call last):\n",
      "  File \"C:\\Users\\Fakhruddin\\Anaconda3\\lib\\site-packages\\flask\\app.py\", line 2446, in wsgi_app\n",
      "    response = self.full_dispatch_request()\n",
      "  File \"C:\\Users\\Fakhruddin\\Anaconda3\\lib\\site-packages\\flask\\app.py\", line 1951, in full_dispatch_request\n",
      "    rv = self.handle_user_exception(e)\n",
      "  File \"C:\\Users\\Fakhruddin\\Anaconda3\\lib\\site-packages\\flask\\app.py\", line 1820, in handle_user_exception\n",
      "    reraise(exc_type, exc_value, tb)\n",
      "  File \"C:\\Users\\Fakhruddin\\Anaconda3\\lib\\site-packages\\flask\\_compat.py\", line 39, in reraise\n",
      "    raise value\n",
      "  File \"C:\\Users\\Fakhruddin\\Anaconda3\\lib\\site-packages\\flask\\app.py\", line 1949, in full_dispatch_request\n",
      "    rv = self.dispatch_request()\n",
      "  File \"C:\\Users\\Fakhruddin\\Anaconda3\\lib\\site-packages\\flask\\app.py\", line 1935, in dispatch_request\n",
      "    return self.view_functions[rule.endpoint](**req.view_args)\n",
      "  File \"C:\\Users\\Fakhruddin\\Anaconda3\\lib\\site-packages\\dash\\dash.py\", line 1031, in dispatch\n",
      "    response.set_data(func(*args, outputs_list=outputs_list))\n",
      "  File \"C:\\Users\\Fakhruddin\\Anaconda3\\lib\\site-packages\\dash\\dash.py\", line 966, in add_context\n",
      "    output_value = func(*args, **kwargs)  # %% callback invoked %%\n",
      "  File \"<ipython-input-40-963591925d46>\", line 56, in update_graph\n",
      "    y = filtered_df['count'],\n",
      "  File \"C:\\Users\\Fakhruddin\\Anaconda3\\lib\\site-packages\\pandas\\core\\frame.py\", line 2800, in __getitem__\n",
      "    indexer = self.columns.get_loc(key)\n",
      "  File \"C:\\Users\\Fakhruddin\\Anaconda3\\lib\\site-packages\\pandas\\core\\indexes\\base.py\", line 2648, in get_loc\n",
      "    return self._engine.get_loc(self._maybe_cast_indexer(key))\n",
      "  File \"pandas\\_libs\\index.pyx\", line 111, in pandas._libs.index.IndexEngine.get_loc\n",
      "  File \"pandas\\_libs\\index.pyx\", line 138, in pandas._libs.index.IndexEngine.get_loc\n",
      "  File \"pandas\\_libs\\hashtable_class_helper.pxi\", line 1619, in pandas._libs.hashtable.PyObjectHashTable.get_item\n",
      "  File \"pandas\\_libs\\hashtable_class_helper.pxi\", line 1627, in pandas._libs.hashtable.PyObjectHashTable.get_item\n",
      "KeyError: 'count'\n"
     ]
    },
    {
     "name": "stdout",
     "output_type": "stream",
     "text": [
      "Exception on /_dash-update-component [POST]\n",
      "Traceback (most recent call last):\n",
      "  File \"C:\\Users\\Fakhruddin\\Anaconda3\\lib\\site-packages\\pandas\\core\\indexes\\base.py\", line 2646, in get_loc\n",
      "    return self._engine.get_loc(key)\n",
      "  File \"pandas\\_libs\\index.pyx\", line 111, in pandas._libs.index.IndexEngine.get_loc\n",
      "  File \"pandas\\_libs\\index.pyx\", line 138, in pandas._libs.index.IndexEngine.get_loc\n",
      "  File \"pandas\\_libs\\hashtable_class_helper.pxi\", line 1619, in pandas._libs.hashtable.PyObjectHashTable.get_item\n",
      "  File \"pandas\\_libs\\hashtable_class_helper.pxi\", line 1627, in pandas._libs.hashtable.PyObjectHashTable.get_item\n",
      "KeyError: 'count'\n",
      "\n",
      "During handling of the above exception, another exception occurred:\n",
      "\n",
      "Traceback (most recent call last):\n",
      "  File \"C:\\Users\\Fakhruddin\\Anaconda3\\lib\\site-packages\\flask\\app.py\", line 2446, in wsgi_app\n",
      "    response = self.full_dispatch_request()\n",
      "  File \"C:\\Users\\Fakhruddin\\Anaconda3\\lib\\site-packages\\flask\\app.py\", line 1951, in full_dispatch_request\n",
      "    rv = self.handle_user_exception(e)\n",
      "  File \"C:\\Users\\Fakhruddin\\Anaconda3\\lib\\site-packages\\flask\\app.py\", line 1820, in handle_user_exception\n",
      "    reraise(exc_type, exc_value, tb)\n",
      "  File \"C:\\Users\\Fakhruddin\\Anaconda3\\lib\\site-packages\\flask\\_compat.py\", line 39, in reraise\n",
      "    raise value\n",
      "  File \"C:\\Users\\Fakhruddin\\Anaconda3\\lib\\site-packages\\flask\\app.py\", line 1949, in full_dispatch_request\n",
      "    rv = self.dispatch_request()\n",
      "  File \"C:\\Users\\Fakhruddin\\Anaconda3\\lib\\site-packages\\flask\\app.py\", line 1935, in dispatch_request\n",
      "    return self.view_functions[rule.endpoint](**req.view_args)\n",
      "  File \"C:\\Users\\Fakhruddin\\Anaconda3\\lib\\site-packages\\dash\\dash.py\", line 1031, in dispatch\n",
      "    response.set_data(func(*args, outputs_list=outputs_list))\n",
      "  File \"C:\\Users\\Fakhruddin\\Anaconda3\\lib\\site-packages\\dash\\dash.py\", line 966, in add_context\n",
      "    output_value = func(*args, **kwargs)  # %% callback invoked %%\n",
      "  File \"<ipython-input-40-963591925d46>\", line 56, in update_graph\n",
      "    y = filtered_df['count'],\n",
      "  File \"C:\\Users\\Fakhruddin\\Anaconda3\\lib\\site-packages\\pandas\\core\\frame.py\", line 2800, in __getitem__\n",
      "    indexer = self.columns.get_loc(key)\n",
      "  File \"C:\\Users\\Fakhruddin\\Anaconda3\\lib\\site-packages\\pandas\\core\\indexes\\base.py\", line 2648, in get_loc\n",
      "    return self._engine.get_loc(self._maybe_cast_indexer(key))\n",
      "  File \"pandas\\_libs\\index.pyx\", line 111, in pandas._libs.index.IndexEngine.get_loc\n",
      "  File \"pandas\\_libs\\index.pyx\", line 138, in pandas._libs.index.IndexEngine.get_loc\n",
      "  File \"pandas\\_libs\\hashtable_class_helper.pxi\", line 1619, in pandas._libs.hashtable.PyObjectHashTable.get_item\n",
      "  File \"pandas\\_libs\\hashtable_class_helper.pxi\", line 1627, in pandas._libs.hashtable.PyObjectHashTable.get_item\n",
      "KeyError: 'count'\n",
      "Exception on /_dash-update-component [POST]\n",
      "Traceback (most recent call last):\n",
      "  File \"C:\\Users\\Fakhruddin\\Anaconda3\\lib\\site-packages\\pandas\\core\\indexes\\base.py\", line 2646, in get_loc\n",
      "    return self._engine.get_loc(key)\n",
      "  File \"pandas\\_libs\\index.pyx\", line 111, in pandas._libs.index.IndexEngine.get_loc\n",
      "  File \"pandas\\_libs\\index.pyx\", line 138, in pandas._libs.index.IndexEngine.get_loc\n",
      "  File \"pandas\\_libs\\hashtable_class_helper.pxi\", line 1619, in pandas._libs.hashtable.PyObjectHashTable.get_item\n",
      "  File \"pandas\\_libs\\hashtable_class_helper.pxi\", line 1627, in pandas._libs.hashtable.PyObjectHashTable.get_item\n",
      "KeyError: 'count'\n",
      "\n",
      "During handling of the above exception, another exception occurred:\n",
      "\n",
      "Traceback (most recent call last):\n",
      "  File \"C:\\Users\\Fakhruddin\\Anaconda3\\lib\\site-packages\\flask\\app.py\", line 2446, in wsgi_app\n",
      "    response = self.full_dispatch_request()\n",
      "  File \"C:\\Users\\Fakhruddin\\Anaconda3\\lib\\site-packages\\flask\\app.py\", line 1951, in full_dispatch_request\n",
      "    rv = self.handle_user_exception(e)\n",
      "  File \"C:\\Users\\Fakhruddin\\Anaconda3\\lib\\site-packages\\flask\\app.py\", line 1820, in handle_user_exception\n",
      "    reraise(exc_type, exc_value, tb)\n",
      "  File \"C:\\Users\\Fakhruddin\\Anaconda3\\lib\\site-packages\\flask\\_compat.py\", line 39, in reraise\n",
      "    raise value\n",
      "  File \"C:\\Users\\Fakhruddin\\Anaconda3\\lib\\site-packages\\flask\\app.py\", line 1949, in full_dispatch_request\n",
      "    rv = self.dispatch_request()\n",
      "  File \"C:\\Users\\Fakhruddin\\Anaconda3\\lib\\site-packages\\flask\\app.py\", line 1935, in dispatch_request\n",
      "    return self.view_functions[rule.endpoint](**req.view_args)\n",
      "  File \"C:\\Users\\Fakhruddin\\Anaconda3\\lib\\site-packages\\dash\\dash.py\", line 1031, in dispatch\n",
      "    response.set_data(func(*args, outputs_list=outputs_list))\n",
      "  File \"C:\\Users\\Fakhruddin\\Anaconda3\\lib\\site-packages\\dash\\dash.py\", line 966, in add_context\n",
      "    output_value = func(*args, **kwargs)  # %% callback invoked %%\n",
      "  File \"<ipython-input-40-963591925d46>\", line 56, in update_graph\n",
      "    y = filtered_df['count'],\n",
      "  File \"C:\\Users\\Fakhruddin\\Anaconda3\\lib\\site-packages\\pandas\\core\\frame.py\", line 2800, in __getitem__\n",
      "    indexer = self.columns.get_loc(key)\n",
      "  File \"C:\\Users\\Fakhruddin\\Anaconda3\\lib\\site-packages\\pandas\\core\\indexes\\base.py\", line 2648, in get_loc\n",
      "    return self._engine.get_loc(self._maybe_cast_indexer(key))\n",
      "  File \"pandas\\_libs\\index.pyx\", line 111, in pandas._libs.index.IndexEngine.get_loc\n",
      "  File \"pandas\\_libs\\index.pyx\", line 138, in pandas._libs.index.IndexEngine.get_loc\n",
      "  File \"pandas\\_libs\\hashtable_class_helper.pxi\", line 1619, in pandas._libs.hashtable.PyObjectHashTable.get_item\n",
      "  File \"pandas\\_libs\\hashtable_class_helper.pxi\", line 1627, in pandas._libs.hashtable.PyObjectHashTable.get_item\n",
      "KeyError: 'count'\n",
      "Exception on /_dash-update-component [POST]\n",
      "Traceback (most recent call last):\n",
      "  File \"C:\\Users\\Fakhruddin\\Anaconda3\\lib\\site-packages\\pandas\\core\\indexes\\base.py\", line 2646, in get_loc\n",
      "    return self._engine.get_loc(key)\n",
      "  File \"pandas\\_libs\\index.pyx\", line 111, in pandas._libs.index.IndexEngine.get_loc\n",
      "  File \"pandas\\_libs\\index.pyx\", line 138, in pandas._libs.index.IndexEngine.get_loc\n",
      "  File \"pandas\\_libs\\hashtable_class_helper.pxi\", line 1619, in pandas._libs.hashtable.PyObjectHashTable.get_item\n",
      "  File \"pandas\\_libs\\hashtable_class_helper.pxi\", line 1627, in pandas._libs.hashtable.PyObjectHashTable.get_item\n",
      "KeyError: 'count'\n",
      "\n",
      "During handling of the above exception, another exception occurred:\n",
      "\n",
      "Traceback (most recent call last):\n",
      "  File \"C:\\Users\\Fakhruddin\\Anaconda3\\lib\\site-packages\\flask\\app.py\", line 2446, in wsgi_app\n",
      "    response = self.full_dispatch_request()\n",
      "  File \"C:\\Users\\Fakhruddin\\Anaconda3\\lib\\site-packages\\flask\\app.py\", line 1951, in full_dispatch_request\n",
      "    rv = self.handle_user_exception(e)\n",
      "  File \"C:\\Users\\Fakhruddin\\Anaconda3\\lib\\site-packages\\flask\\app.py\", line 1820, in handle_user_exception\n",
      "    reraise(exc_type, exc_value, tb)\n",
      "  File \"C:\\Users\\Fakhruddin\\Anaconda3\\lib\\site-packages\\flask\\_compat.py\", line 39, in reraise\n",
      "    raise value\n",
      "  File \"C:\\Users\\Fakhruddin\\Anaconda3\\lib\\site-packages\\flask\\app.py\", line 1949, in full_dispatch_request\n",
      "    rv = self.dispatch_request()\n",
      "  File \"C:\\Users\\Fakhruddin\\Anaconda3\\lib\\site-packages\\flask\\app.py\", line 1935, in dispatch_request\n",
      "    return self.view_functions[rule.endpoint](**req.view_args)\n",
      "  File \"C:\\Users\\Fakhruddin\\Anaconda3\\lib\\site-packages\\dash\\dash.py\", line 1031, in dispatch\n",
      "    response.set_data(func(*args, outputs_list=outputs_list))\n",
      "  File \"C:\\Users\\Fakhruddin\\Anaconda3\\lib\\site-packages\\dash\\dash.py\", line 966, in add_context\n",
      "    output_value = func(*args, **kwargs)  # %% callback invoked %%\n",
      "  File \"<ipython-input-40-963591925d46>\", line 56, in update_graph\n",
      "    y = filtered_df['count'],\n",
      "  File \"C:\\Users\\Fakhruddin\\Anaconda3\\lib\\site-packages\\pandas\\core\\frame.py\", line 2800, in __getitem__\n",
      "    indexer = self.columns.get_loc(key)\n",
      "  File \"C:\\Users\\Fakhruddin\\Anaconda3\\lib\\site-packages\\pandas\\core\\indexes\\base.py\", line 2648, in get_loc\n",
      "    return self._engine.get_loc(self._maybe_cast_indexer(key))\n",
      "  File \"pandas\\_libs\\index.pyx\", line 111, in pandas._libs.index.IndexEngine.get_loc\n",
      "  File \"pandas\\_libs\\index.pyx\", line 138, in pandas._libs.index.IndexEngine.get_loc\n",
      "  File \"pandas\\_libs\\hashtable_class_helper.pxi\", line 1619, in pandas._libs.hashtable.PyObjectHashTable.get_item\n",
      "  File \"pandas\\_libs\\hashtable_class_helper.pxi\", line 1627, in pandas._libs.hashtable.PyObjectHashTable.get_item\n",
      "KeyError: 'count'\n"
     ]
    },
    {
     "name": "stdout",
     "output_type": "stream",
     "text": [
      "Exception on /_dash-update-component [POST]\n",
      "Traceback (most recent call last):\n",
      "  File \"C:\\Users\\Fakhruddin\\Anaconda3\\lib\\site-packages\\pandas\\core\\indexes\\base.py\", line 2646, in get_loc\n",
      "    return self._engine.get_loc(key)\n",
      "  File \"pandas\\_libs\\index.pyx\", line 111, in pandas._libs.index.IndexEngine.get_loc\n",
      "  File \"pandas\\_libs\\index.pyx\", line 138, in pandas._libs.index.IndexEngine.get_loc\n",
      "  File \"pandas\\_libs\\hashtable_class_helper.pxi\", line 1619, in pandas._libs.hashtable.PyObjectHashTable.get_item\n",
      "  File \"pandas\\_libs\\hashtable_class_helper.pxi\", line 1627, in pandas._libs.hashtable.PyObjectHashTable.get_item\n",
      "KeyError: 'count'\n",
      "\n",
      "During handling of the above exception, another exception occurred:\n",
      "\n",
      "Traceback (most recent call last):\n",
      "  File \"C:\\Users\\Fakhruddin\\Anaconda3\\lib\\site-packages\\flask\\app.py\", line 2446, in wsgi_app\n",
      "    response = self.full_dispatch_request()\n",
      "  File \"C:\\Users\\Fakhruddin\\Anaconda3\\lib\\site-packages\\flask\\app.py\", line 1951, in full_dispatch_request\n",
      "    rv = self.handle_user_exception(e)\n",
      "  File \"C:\\Users\\Fakhruddin\\Anaconda3\\lib\\site-packages\\flask\\app.py\", line 1820, in handle_user_exception\n",
      "    reraise(exc_type, exc_value, tb)\n",
      "  File \"C:\\Users\\Fakhruddin\\Anaconda3\\lib\\site-packages\\flask\\_compat.py\", line 39, in reraise\n",
      "    raise value\n",
      "  File \"C:\\Users\\Fakhruddin\\Anaconda3\\lib\\site-packages\\flask\\app.py\", line 1949, in full_dispatch_request\n",
      "    rv = self.dispatch_request()\n",
      "  File \"C:\\Users\\Fakhruddin\\Anaconda3\\lib\\site-packages\\flask\\app.py\", line 1935, in dispatch_request\n",
      "    return self.view_functions[rule.endpoint](**req.view_args)\n",
      "  File \"C:\\Users\\Fakhruddin\\Anaconda3\\lib\\site-packages\\dash\\dash.py\", line 1031, in dispatch\n",
      "    response.set_data(func(*args, outputs_list=outputs_list))\n",
      "  File \"C:\\Users\\Fakhruddin\\Anaconda3\\lib\\site-packages\\dash\\dash.py\", line 966, in add_context\n",
      "    output_value = func(*args, **kwargs)  # %% callback invoked %%\n",
      "  File \"<ipython-input-40-963591925d46>\", line 56, in update_graph\n",
      "    y = filtered_df['count'],\n",
      "  File \"C:\\Users\\Fakhruddin\\Anaconda3\\lib\\site-packages\\pandas\\core\\frame.py\", line 2800, in __getitem__\n",
      "    indexer = self.columns.get_loc(key)\n",
      "  File \"C:\\Users\\Fakhruddin\\Anaconda3\\lib\\site-packages\\pandas\\core\\indexes\\base.py\", line 2648, in get_loc\n",
      "    return self._engine.get_loc(self._maybe_cast_indexer(key))\n",
      "  File \"pandas\\_libs\\index.pyx\", line 111, in pandas._libs.index.IndexEngine.get_loc\n",
      "  File \"pandas\\_libs\\index.pyx\", line 138, in pandas._libs.index.IndexEngine.get_loc\n",
      "  File \"pandas\\_libs\\hashtable_class_helper.pxi\", line 1619, in pandas._libs.hashtable.PyObjectHashTable.get_item\n",
      "  File \"pandas\\_libs\\hashtable_class_helper.pxi\", line 1627, in pandas._libs.hashtable.PyObjectHashTable.get_item\n",
      "KeyError: 'count'\n",
      "Exception on /_dash-update-component [POST]\n",
      "Traceback (most recent call last):\n",
      "  File \"C:\\Users\\Fakhruddin\\Anaconda3\\lib\\site-packages\\pandas\\core\\indexes\\base.py\", line 2646, in get_loc\n",
      "    return self._engine.get_loc(key)\n",
      "  File \"pandas\\_libs\\index.pyx\", line 111, in pandas._libs.index.IndexEngine.get_loc\n",
      "  File \"pandas\\_libs\\index.pyx\", line 138, in pandas._libs.index.IndexEngine.get_loc\n",
      "  File \"pandas\\_libs\\hashtable_class_helper.pxi\", line 1619, in pandas._libs.hashtable.PyObjectHashTable.get_item\n",
      "  File \"pandas\\_libs\\hashtable_class_helper.pxi\", line 1627, in pandas._libs.hashtable.PyObjectHashTable.get_item\n",
      "KeyError: 'count'\n",
      "\n",
      "During handling of the above exception, another exception occurred:\n",
      "\n",
      "Traceback (most recent call last):\n",
      "  File \"C:\\Users\\Fakhruddin\\Anaconda3\\lib\\site-packages\\flask\\app.py\", line 2446, in wsgi_app\n",
      "    response = self.full_dispatch_request()\n",
      "  File \"C:\\Users\\Fakhruddin\\Anaconda3\\lib\\site-packages\\flask\\app.py\", line 1951, in full_dispatch_request\n",
      "    rv = self.handle_user_exception(e)\n",
      "  File \"C:\\Users\\Fakhruddin\\Anaconda3\\lib\\site-packages\\flask\\app.py\", line 1820, in handle_user_exception\n",
      "    reraise(exc_type, exc_value, tb)\n",
      "  File \"C:\\Users\\Fakhruddin\\Anaconda3\\lib\\site-packages\\flask\\_compat.py\", line 39, in reraise\n",
      "    raise value\n",
      "  File \"C:\\Users\\Fakhruddin\\Anaconda3\\lib\\site-packages\\flask\\app.py\", line 1949, in full_dispatch_request\n",
      "    rv = self.dispatch_request()\n",
      "  File \"C:\\Users\\Fakhruddin\\Anaconda3\\lib\\site-packages\\flask\\app.py\", line 1935, in dispatch_request\n",
      "    return self.view_functions[rule.endpoint](**req.view_args)\n",
      "  File \"C:\\Users\\Fakhruddin\\Anaconda3\\lib\\site-packages\\dash\\dash.py\", line 1031, in dispatch\n",
      "    response.set_data(func(*args, outputs_list=outputs_list))\n",
      "  File \"C:\\Users\\Fakhruddin\\Anaconda3\\lib\\site-packages\\dash\\dash.py\", line 966, in add_context\n",
      "    output_value = func(*args, **kwargs)  # %% callback invoked %%\n",
      "  File \"<ipython-input-40-963591925d46>\", line 56, in update_graph\n",
      "    y = filtered_df['count'],\n",
      "  File \"C:\\Users\\Fakhruddin\\Anaconda3\\lib\\site-packages\\pandas\\core\\frame.py\", line 2800, in __getitem__\n",
      "    indexer = self.columns.get_loc(key)\n",
      "  File \"C:\\Users\\Fakhruddin\\Anaconda3\\lib\\site-packages\\pandas\\core\\indexes\\base.py\", line 2648, in get_loc\n",
      "    return self._engine.get_loc(self._maybe_cast_indexer(key))\n",
      "  File \"pandas\\_libs\\index.pyx\", line 111, in pandas._libs.index.IndexEngine.get_loc\n",
      "  File \"pandas\\_libs\\index.pyx\", line 138, in pandas._libs.index.IndexEngine.get_loc\n",
      "  File \"pandas\\_libs\\hashtable_class_helper.pxi\", line 1619, in pandas._libs.hashtable.PyObjectHashTable.get_item\n",
      "  File \"pandas\\_libs\\hashtable_class_helper.pxi\", line 1627, in pandas._libs.hashtable.PyObjectHashTable.get_item\n",
      "KeyError: 'count'\n",
      "Exception on /_dash-update-component [POST]\n",
      "Traceback (most recent call last):\n",
      "  File \"C:\\Users\\Fakhruddin\\Anaconda3\\lib\\site-packages\\pandas\\core\\indexes\\base.py\", line 2646, in get_loc\n",
      "    return self._engine.get_loc(key)\n",
      "  File \"pandas\\_libs\\index.pyx\", line 111, in pandas._libs.index.IndexEngine.get_loc\n",
      "  File \"pandas\\_libs\\index.pyx\", line 138, in pandas._libs.index.IndexEngine.get_loc\n",
      "  File \"pandas\\_libs\\hashtable_class_helper.pxi\", line 1619, in pandas._libs.hashtable.PyObjectHashTable.get_item\n",
      "  File \"pandas\\_libs\\hashtable_class_helper.pxi\", line 1627, in pandas._libs.hashtable.PyObjectHashTable.get_item\n",
      "KeyError: 'count'\n",
      "\n",
      "During handling of the above exception, another exception occurred:\n",
      "\n",
      "Traceback (most recent call last):\n",
      "  File \"C:\\Users\\Fakhruddin\\Anaconda3\\lib\\site-packages\\flask\\app.py\", line 2446, in wsgi_app\n",
      "    response = self.full_dispatch_request()\n",
      "  File \"C:\\Users\\Fakhruddin\\Anaconda3\\lib\\site-packages\\flask\\app.py\", line 1951, in full_dispatch_request\n",
      "    rv = self.handle_user_exception(e)\n",
      "  File \"C:\\Users\\Fakhruddin\\Anaconda3\\lib\\site-packages\\flask\\app.py\", line 1820, in handle_user_exception\n",
      "    reraise(exc_type, exc_value, tb)\n",
      "  File \"C:\\Users\\Fakhruddin\\Anaconda3\\lib\\site-packages\\flask\\_compat.py\", line 39, in reraise\n",
      "    raise value\n",
      "  File \"C:\\Users\\Fakhruddin\\Anaconda3\\lib\\site-packages\\flask\\app.py\", line 1949, in full_dispatch_request\n",
      "    rv = self.dispatch_request()\n",
      "  File \"C:\\Users\\Fakhruddin\\Anaconda3\\lib\\site-packages\\flask\\app.py\", line 1935, in dispatch_request\n",
      "    return self.view_functions[rule.endpoint](**req.view_args)\n",
      "  File \"C:\\Users\\Fakhruddin\\Anaconda3\\lib\\site-packages\\dash\\dash.py\", line 1031, in dispatch\n",
      "    response.set_data(func(*args, outputs_list=outputs_list))\n",
      "  File \"C:\\Users\\Fakhruddin\\Anaconda3\\lib\\site-packages\\dash\\dash.py\", line 966, in add_context\n",
      "    output_value = func(*args, **kwargs)  # %% callback invoked %%\n",
      "  File \"<ipython-input-40-963591925d46>\", line 56, in update_graph\n",
      "    y = filtered_df['count'],\n",
      "  File \"C:\\Users\\Fakhruddin\\Anaconda3\\lib\\site-packages\\pandas\\core\\frame.py\", line 2800, in __getitem__\n",
      "    indexer = self.columns.get_loc(key)\n",
      "  File \"C:\\Users\\Fakhruddin\\Anaconda3\\lib\\site-packages\\pandas\\core\\indexes\\base.py\", line 2648, in get_loc\n",
      "    return self._engine.get_loc(self._maybe_cast_indexer(key))\n",
      "  File \"pandas\\_libs\\index.pyx\", line 111, in pandas._libs.index.IndexEngine.get_loc\n",
      "  File \"pandas\\_libs\\index.pyx\", line 138, in pandas._libs.index.IndexEngine.get_loc\n",
      "  File \"pandas\\_libs\\hashtable_class_helper.pxi\", line 1619, in pandas._libs.hashtable.PyObjectHashTable.get_item\n",
      "  File \"pandas\\_libs\\hashtable_class_helper.pxi\", line 1627, in pandas._libs.hashtable.PyObjectHashTable.get_item\n",
      "KeyError: 'count'\n"
     ]
    },
    {
     "name": "stderr",
     "output_type": "stream",
     "text": [
      "127.0.0.1 - - [27/Jun/2020 15:18:24] \"\u001b[1m\u001b[35mPOST /_dash-update-component HTTP/1.1\u001b[0m\" 500 -\n"
     ]
    }
   ],
   "source": [
    "app = dash.Dash()\n",
    "app.layout = html.Div([\n",
    "    html.H1('State Order type time analysis'),\n",
    "    html.Div([\n",
    "        html.H3('Select State:', style={'paddingRight':'30px'}),\n",
    "        # replace dcc.Input with dcc.Options, set options=options\n",
    "        dcc.Dropdown(\n",
    "            id='my_state',\n",
    "            options=[{'label':i,'value':i} for i in df.State.unique()],\n",
    "            value='Maharashtra',\n",
    "            multi=False\n",
    "        )\n",
    "        ], style={'display':'inline-block', 'verticalAlign':'top', 'width':'30%'}),\n",
    "      html.Div([\n",
    "        html.H3('Select start and end dates:'),\n",
    "        dcc.DatePickerRange(\n",
    "            id='my_date_picker',\n",
    "            min_date_allowed=df['JobCard Date'].min(),\n",
    "            max_date_allowed=df['JobCard Date'].max(),\n",
    "            start_date=datetime(2012,5,1),\n",
    "            end_date=datetime(2012,6,1)\n",
    "        )\n",
    "    ], style={'display':'inline-block'}),\n",
    "     html.Div([\n",
    "        html.Button(\n",
    "            id='submit-button',\n",
    "            n_clicks=0,\n",
    "            children='Submit',\n",
    "            style={'fontSize':24, 'marginLeft':'30px'}\n",
    "        ),\n",
    "    ], style={'display':'inline-block'}),\n",
    "     dcc.Graph(\n",
    "        id='my_graph'\n",
    "    )\n",
    "    \n",
    "])\n",
    "#######################################################################################\n",
    "@app.callback(\n",
    "    Output('my_graph', 'figure'),\n",
    "    [Input('submit-button', 'n_clicks')],\n",
    "    [State('my_state', 'value'),\n",
    "    State('my_date_picker', 'start_date'),\n",
    "    State('my_date_picker', 'end_date')])\n",
    "\n",
    "#######################################################################################\n",
    "def update_graph(n_clicks,selected_state,start_date,end_date):\n",
    "    start = datetime.strptime(start_date[:10], '%Y-%m-%d')\n",
    "    end = datetime.strptime(end_date[:10], '%Y-%m-%d')\n",
    "    filtered_df=df[(df['State']==selected_state) &\n",
    "                   (df['JobCard Date']>=start)&(df['JobCard Date']<=end)\n",
    "                  ]\n",
    "    traces=[]\n",
    "            \n",
    "    trace1= go.Scatter(\n",
    "                    x = filtered_df['JobCard Date'],\n",
    "                    y = filtered_df['count'],\n",
    "                    name = selected_state,\n",
    "                  #  mode = 'markers',\n",
    "                    mode='markers',\n",
    "                    #marker = {\n",
    "                        #'size': 12,\n",
    "                       # 'color': 'rgb(51,204,153)',\n",
    "                       #'symbol': 'pentagon',\n",
    "                      #  'line': {'width': 2},\n",
    "                    text=filtered_df['Order Type']\n",
    "                        \n",
    "                )\n",
    "    traces.append(trace1)\n",
    "    return {\n",
    "        'data': traces,\n",
    "        'layout': go.Layout(\n",
    "            title='Revenue Generated in a State on the basis of Car Brands ',\n",
    "            xaxis={ 'title': 'Car Brands'},\n",
    "            yaxis={'title': 'Revenue'},\n",
    "            hovermode='closest')\n",
    "        \n",
    "    \n",
    "\n",
    "        } \n",
    "if __name__ == '__main__':\n",
    "    app.run_server()    "
   ]
  },
  {
   "cell_type": "code",
   "execution_count": 58,
   "metadata": {},
   "outputs": [
    {
     "name": "stdout",
     "output_type": "stream",
     "text": [
      "Dash is running on http://127.0.0.1:8050/\n",
      "\n",
      "Dash is running on http://127.0.0.1:8050/\n",
      "\n",
      "Dash is running on http://127.0.0.1:8050/\n",
      "\n",
      "Dash is running on http://127.0.0.1:8050/\n",
      "\n",
      "Dash is running on http://127.0.0.1:8050/\n",
      "\n",
      "Dash is running on http://127.0.0.1:8050/\n",
      "\n",
      "Dash is running on http://127.0.0.1:8050/\n",
      "\n",
      "Dash is running on http://127.0.0.1:8050/\n",
      "\n",
      "Dash is running on http://127.0.0.1:8050/\n",
      "\n",
      "Dash is running on http://127.0.0.1:8050/\n",
      "\n",
      "Dash is running on http://127.0.0.1:8050/\n",
      "\n",
      "Dash is running on http://127.0.0.1:8050/\n",
      "\n",
      "Dash is running on http://127.0.0.1:8050/\n",
      "\n",
      "Dash is running on http://127.0.0.1:8050/\n",
      "\n",
      "Dash is running on http://127.0.0.1:8050/\n",
      "\n",
      "Dash is running on http://127.0.0.1:8050/\n",
      "\n",
      "Dash is running on http://127.0.0.1:8050/\n",
      "\n",
      "Dash is running on http://127.0.0.1:8050/\n",
      "\n",
      "Dash is running on http://127.0.0.1:8050/\n",
      "\n",
      "Dash is running on http://127.0.0.1:8050/\n",
      "\n",
      "Dash is running on http://127.0.0.1:8050/\n",
      "\n",
      "Dash is running on http://127.0.0.1:8050/\n",
      "\n",
      "Dash is running on http://127.0.0.1:8050/\n",
      "\n",
      " Warning: This is a development server. Do not use app.run_server\n",
      " Warning: This is a development server. Do not use app.run_server\n",
      " Warning: This is a development server. Do not use app.run_server\n",
      " Warning: This is a development server. Do not use app.run_server\n",
      " Warning: This is a development server. Do not use app.run_server\n",
      " Warning: This is a development server. Do not use app.run_server\n",
      " Warning: This is a development server. Do not use app.run_server\n",
      " Warning: This is a development server. Do not use app.run_server\n",
      " Warning: This is a development server. Do not use app.run_server\n",
      " Warning: This is a development server. Do not use app.run_server\n",
      " Warning: This is a development server. Do not use app.run_server\n",
      " Warning: This is a development server. Do not use app.run_server\n",
      " Warning: This is a development server. Do not use app.run_server\n",
      " Warning: This is a development server. Do not use app.run_server\n",
      " Warning: This is a development server. Do not use app.run_server\n",
      " Warning: This is a development server. Do not use app.run_server\n",
      " Warning: This is a development server. Do not use app.run_server\n",
      " Warning: This is a development server. Do not use app.run_server\n",
      " Warning: This is a development server. Do not use app.run_server\n",
      " Warning: This is a development server. Do not use app.run_server\n",
      " Warning: This is a development server. Do not use app.run_server\n",
      " Warning: This is a development server. Do not use app.run_server\n",
      " Warning: This is a development server. Do not use app.run_server\n",
      " in production, use a production WSGI server like gunicorn instead.\n",
      "\n",
      " in production, use a production WSGI server like gunicorn instead.\n",
      "\n",
      " in production, use a production WSGI server like gunicorn instead.\n",
      "\n",
      " in production, use a production WSGI server like gunicorn instead.\n",
      "\n",
      " in production, use a production WSGI server like gunicorn instead.\n",
      "\n",
      " in production, use a production WSGI server like gunicorn instead.\n",
      "\n",
      " in production, use a production WSGI server like gunicorn instead.\n",
      "\n",
      " in production, use a production WSGI server like gunicorn instead.\n",
      "\n",
      " in production, use a production WSGI server like gunicorn instead.\n",
      "\n",
      " in production, use a production WSGI server like gunicorn instead.\n",
      "\n",
      " in production, use a production WSGI server like gunicorn instead.\n",
      "\n",
      " in production, use a production WSGI server like gunicorn instead.\n",
      "\n",
      " in production, use a production WSGI server like gunicorn instead.\n",
      "\n",
      " in production, use a production WSGI server like gunicorn instead.\n",
      "\n",
      " in production, use a production WSGI server like gunicorn instead.\n",
      "\n",
      " in production, use a production WSGI server like gunicorn instead.\n",
      "\n",
      " in production, use a production WSGI server like gunicorn instead.\n",
      "\n",
      " in production, use a production WSGI server like gunicorn instead.\n",
      "\n",
      " in production, use a production WSGI server like gunicorn instead.\n",
      "\n",
      " in production, use a production WSGI server like gunicorn instead.\n",
      "\n",
      " in production, use a production WSGI server like gunicorn instead.\n",
      "\n",
      " in production, use a production WSGI server like gunicorn instead.\n",
      "\n",
      " in production, use a production WSGI server like gunicorn instead.\n",
      "\n",
      " * Serving Flask app \"__main__\" (lazy loading)\n",
      " * Environment: production\n",
      "   WARNING: This is a development server. Do not use it in a production deployment.\n",
      "   Use a production WSGI server instead.\n",
      " * Debug mode: off\n"
     ]
    },
    {
     "name": "stderr",
     "output_type": "stream",
     "text": [
      " * Running on http://127.0.0.1:8050/ (Press CTRL+C to quit)\n",
      "127.0.0.1 - - [27/Jun/2020 18:08:54] \"\u001b[37mGET / HTTP/1.1\u001b[0m\" 200 -\n",
      "127.0.0.1 - - [27/Jun/2020 18:08:54] \"\u001b[37mGET /_dash-layout HTTP/1.1\u001b[0m\" 200 -\n",
      "127.0.0.1 - - [27/Jun/2020 18:08:54] \"\u001b[37mGET /_dash-dependencies HTTP/1.1\u001b[0m\" 200 -\n",
      "127.0.0.1 - - [27/Jun/2020 18:08:54] \"\u001b[37mPOST /_dash-update-component HTTP/1.1\u001b[0m\" 200 -\n",
      "127.0.0.1 - - [27/Jun/2020 18:09:20] \"\u001b[37mPOST /_dash-update-component HTTP/1.1\u001b[0m\" 200 -\n",
      "127.0.0.1 - - [27/Jun/2020 18:09:31] \"\u001b[37mPOST /_dash-update-component HTTP/1.1\u001b[0m\" 200 -\n"
     ]
    }
   ],
   "source": [
    "app = dash.Dash(__name__)\n",
    "######################################################################################################\n",
    "#Layout of the dashboard:\n",
    "app.layout= html.Div([\n",
    "#####################################################################################################\n",
    "      html.Div([\n",
    "        html.Label(['Based on Make State revenue Analysis']),\n",
    "        dcc.Dropdown(\n",
    "            id='my_state',\n",
    "            options=[{'label':i,'value':i} for i in df.State.unique()],\n",
    "            value='Maharashtra',\n",
    "            multi=False,\n",
    "            clearable=False,\n",
    "            style={'width':'50%'}\n",
    "        ),\n",
    "    ]),\n",
    "\n",
    "    html.Div([\n",
    "        dcc.Graph(id='State_Make_revenue_graph',\n",
    "                 style={'width':'70%'}\n",
    "                 )\n",
    "    ])\n",
    "###################################################################################    \n",
    "    ])\n",
    "@app.callback(Output('State_Make_revenue_graph', 'figure'),\n",
    "              [Input('my_state','value')])\n",
    "def update_figure(selected_state):\n",
    "    filtered_df = df[df['State'] == selected_state]\n",
    "    traces=[]\n",
    "    #for selected_state in df1.State.unique():\n",
    "    \n",
    "    trace1 = go.Line(\n",
    "             x = filtered_df['JobCard Date'],\n",
    "             y=filtered_df['Count'],   \n",
    "            name = selected_state,\n",
    "            text=df['Order Type'],\n",
    "            mode='lines+markers')\n",
    "            #marker = dict(color = 'rgba(239,222,205, 0.7)',\n",
    "            #line=dict(color='rgb(0,0,0)',width=1.5)))\n",
    "    traces.append(trace1)\n",
    "    \n",
    "    \n",
    "\n",
    "    return {\n",
    "        'data': traces,\n",
    "        'layout': go.Layout(\n",
    "            title='Revenue Generated in a State on the basis of Car Brands ',\n",
    "            xaxis={ 'title': 'Car Brands'},\n",
    "            yaxis={'title': 'Revenue'},\n",
    "            hovermode='closest')\n",
    "        \n",
    "    \n",
    "\n",
    "        }\n",
    "if __name__ == '__main__':\n",
    "    app.run_server()"
   ]
  },
  {
   "cell_type": "code",
   "execution_count": null,
   "metadata": {},
   "outputs": [],
   "source": []
  }
 ],
 "metadata": {
  "kernelspec": {
   "display_name": "Python 3",
   "language": "python",
   "name": "python3"
  },
  "language_info": {
   "codemirror_mode": {
    "name": "ipython",
    "version": 3
   },
   "file_extension": ".py",
   "mimetype": "text/x-python",
   "name": "python",
   "nbconvert_exporter": "python",
   "pygments_lexer": "ipython3",
   "version": "3.7.3"
  }
 },
 "nbformat": 4,
 "nbformat_minor": 2
}
